Workbook

Sheet Resumen
C1: Validación | D1: =D3+F3+G3+I3+J3+E3+H3 -> 3225204 | F1: =D1-BASE!Q1 -> 0 | K1: =K3-'Eventos B2B_MKT y Turnos DT'!P2 -> 0 | L1: =L3-'Eventos B2B_MKT y Turnos DT'!P3 -> 0 | M1: =M3-'Eventos B2B_MKT y Turnos DT'!P4 -> 0 | N1: =N3-Incidencias!K2 -> 0 | O1: =(D1+K3+L3+M3+N3)-O3 -> 0
D3: =SUBTOTAL(9,D6:D99) -> 1888913 | E3: =SUBTOTAL(9,E6:E99) -> 45378 | F3: =SUBTOTAL(9,F6:F99) -> 1151594 | G3: =SUBTOTAL(9,G6:G99) -> 0 | H3: =SUBTOTAL(9,H6:H99) -> 22689 | I3: =SUBTOTAL(9,I6:I99) -> 68067 | J3: =SUBTOTAL(9,J6:J99) -> 48563 | K3: =SUBTOTAL(9,K6:K99) -> 509750 | ... Q3: =SUBTOTAL(9,Q6:Q99) -> 74426 | R3: =IFERROR(Q3/O3,0) -> 0.018119793 | S3: =SUBTOTAL(9,S6:S99) -> 164999.89 | T3: =SUBTOTAL(9,T6:T99) -> 3406631.1 | U3: =+IF(O3*(1-0.1525)-Q3=T3,"OK","REVISAR") -> OK
B5: RUT | C5: NOMBRE TERAPEUTA | D5: B2C | E5: CERTIFICADO B2C | F5: HOTEL | G5: B2B | H5: CERTIFICADO B2B | I5: ALIANZA | J5: MARKETING | K5: EVENTO B2B | L5: TURNO HOTEL DT | M5: EVENTO MKT | N5: INCIDENCIAS | O5: MONTO BOLETA | P5: DEUDA TOTAL | Q5: DCTO QUINCENA | R5: % DCTO | S5: DEUDA RESTANTE | T5: A PAGO QUINCENA | U5: VALIDADOR
B6: =Nómina!D3 -> 20025768-5 | C6: =Nómina!E3 -> ADOLFO STEPHEN PFENG ROJAS | D6: =SUMIFS(BASE!$Q$3:$Q$453,BASE!$O$3:$O$453,Resumen!D$5,BASE!$B$3:$B$453,Resumen!$B6) -> 0 | E6: =SUMIFS(BASE!$Q$3:$Q$453,BASE!$O$3:$O$453,Resumen!E$5,BASE!$B$3:$B$453,Resumen!$B6) -> 0 | F6: =SUMIFS(BASE!$Q$3:$Q$453,BASE!$O$3:$O$453,Resumen!F$5,BASE!$B$3:$B$453,Resumen!$B6) -> 0 | G6: =SUMIFS(BASE!$Q$3:$Q$453,BASE!$O$3:$O$453,Resumen!G$5,BASE!$B$3:$B$453,Resumen!$B6) -> 0 | H6: =SUMIFS(BASE!$Q$3:$Q$453,BASE!$O$3:$O$453,Resumen!H$5,BASE!$B$3:$B$453,Resumen!$B6) -> 0 | I6: =SUMIFS(BASE!$Q$3:$Q$453,BASE!$O$3:$O$453,Resumen!I$5,BASE!$B$3:$B$453,Resumen!$B6) -> 0 | J6: =SUMIFS(BASE!$Q$3:$Q$453,BASE!$O$3:$O$453,Resumen!J$5,BASE!$B$3:$B$453,Resumen!$B6) -> 0 | K6: =SUMIFS('Eventos B2B_MKT y Turnos DT'!$K$6:$K$456,'Eventos B2B_MKT y Turnos DT'!$D$6:$D$456,Resumen!$B6,'Eventos B2B_MKT y Turnos DT'!$G$6:$G$456,"B2B") -> 0 | L6: =SUMIFS('Eventos B2B_MKT y Turnos DT'!$K$6:$K$456,'Eventos B2B_MKT y Turnos DT'!$D$6:$D$456,Resumen!$B6,'Eventos B2B_MKT y Turnos DT'!$G$6:$G$456,"Hotel") -> 0 | M6: =SUMIFS('Eventos B2B_MKT y Turnos DT'!$K$6:$K$456,'Eventos B2B_MKT y Turnos DT'!$D$6:$D$456,Resumen!$B6,'Eventos B2B_MKT y Turnos DT'!$G$6:$G$456,"Marketing") -> 0 | N6: =SUMIF(Incidencias!$E$4:$E$89,$B6,Incidencias!$K$4:$K$89) -> 0 | O6: =SUM(D6:N6) -> 0 | P6: 128400 | R6: =IFERROR(Q6/O6,0) -> 0 | S6: =IFERROR(P6-Q6,"") -> 128400 | T6: =O6*(1-0.1525)-Q6 -> 0
B7: =Nómina!D4 -> 13715658-K | C7: =Nómina!E4 -> ALEJANDRA PAZ SANCHEZ LENERO | D7: =SUMIFS(BASE!$Q$3:$Q$453,BASE!$O$3:$O$453,Resumen!D$5,BASE!$B$3:$B$453,Resumen!$B7) -> 68067 | E7: =SUMIFS(BASE!$Q$3:$Q$453,BASE!$O$3:$O$453,Resumen!E$5,BASE!$B$3:$B$453,Resumen!$B7) -> 0 | F7: =SUMIFS(BASE!$Q$3:$Q$453,BASE!$O$3:$O$453,Resumen!F$5,BASE!$B$3:$B$453,Resumen!$B7) -> 110924 | G7: =SUMIFS(BASE!$Q$3:$Q$453,BASE!$O$3:$O$453,Resumen!G$5,BASE!$B$3:$B$453,Resumen!$B7) -> 0 | H7: =SUMIFS(BASE!$Q$3:$Q$453,BASE!$O$3:$O$453,Resumen!H$5,BASE!$B$3:$B$453,Resumen!$B7) -> 0 | I7: =SUMIFS(BASE!$Q$3:$Q$453,BASE!$O$3:$O$453,Resumen!I$5,BASE!$B$3:$B$453,Resumen!$B7) -> 0 | J7: =SUMIFS(BASE!$Q$3:$Q$453,BASE!$O$3:$O$453,Resumen!J$5,BASE!$B$3:$B$453,Resumen!$B7) -> 0 | K7: =SUMIFS('Eventos B2B_MKT y Turnos DT'!$K$6:$K$456,'Eventos B2B_MKT y Turnos DT'!$D$6:$D$456,Resumen!$B7,'Eventos B2B_MKT y Turnos DT'!$G$6:$G$456,"B2B") -> 0 | L7: =SUMIFS('Eventos B2B_MKT y Turnos DT'!$K$6:$K$456,'Eventos B2B_MKT y Turnos DT'!$D$6:$D$456,Resumen!$B7,'Eventos B2B_MKT y Turnos DT'!$G$6:$G$456,"Hotel") -> 23392 | M7: =SUMIFS('Eventos B2B_MKT y Turnos DT'!$K$6:$K$456,'Eventos B2B_MKT y Turnos DT'!$D$6:$D$456,Resumen!$B7,'Eventos B2B_MKT y Turnos DT'!$G$6:$G$456,"Marketing") -> 0 | N7: =SUMIF(Incidencias!$E$4:$E$89,$B7,Incidencias!$K$4:$K$89) -> 0 | O7: =SUM(D7:N7) -> 202383 | P7: 0 | Q7: =+IF(AND(P7<>0,P7>O7*0.2),O7*0.2,P7) -> 0 | R7: =IFERROR(Q7/O7,0) -> 0 | S7: =IFERROR(P7-Q7,"") -> 0 | T7: =O7*(1-0.1525)-Q7 -> 171519.59 | U7: =+IF(O7*(1-0.1525)-Q7=T7,"OK","REVISAR") -> OK
B8: =Nómina!D5 -> 15939313-5 | C8: =Nómina!E5 -> ANA MARIA ORTEGA RIVAS | D8: =SUMIFS(BASE!$Q$3:$Q$453,BASE!$O$3:$O$453,Resumen!D$5,BASE!$B$3:$B$453,Resumen!$B8) -> 0 | E8: =SUMIFS(BASE!$Q$3:$Q$453,BASE!$O$3:$O$453,Resumen!E$5,BASE!$B$3:$B$453,Resumen!$B8) -> 0 | F8: =SUMIFS(BASE!$Q$3:$Q$453,BASE!$O$3:$O$453,Resumen!F$5,BASE!$B$3:$B$453,Resumen!$B8) -> 0 | G8: =SUMIFS(BASE!$Q$3:$Q$453,BASE!$O$3:$O$453,Resumen!G$5,BASE!$B$3:$B$453,Resumen!$B8) -> 0 | H8: =SUMIFS(BASE!$Q$3:$Q$453,BASE!$O$3:$O$453,Resumen!H$5,BASE!$B$3:$B$453,Resumen!$B8) -> 0 | I8: =SUMIFS(BASE!$Q$3:$Q$453,BASE!$O$3:$O$453,Resumen!I$5,BASE!$B$3:$B$453,Resumen!$B8) -> 0 | J8: =SUMIFS(BASE!$Q$3:$Q$453,BASE!$O$3:$O$453,Resumen!J$5,BASE!$B$3:$B$453,Resumen!$B8) -> 0 | K8: =SUMIFS('Eventos B2B_MKT y Turnos DT'!$K$6:$K$456,'Eventos B2B_MKT y Turnos DT'!$D$6:$D$456,Resumen!$B8,'Eventos B2B_MKT y Turnos DT'!$G$6:$G$456,"B2B") -> 0 | L8: =SUMIFS('Eventos B2B_MKT y Turnos DT'!$K$6:$K$456,'Eventos B2B_MKT y Turnos DT'!$D$6:$D$456,Resumen!$B8,'Eventos B2B_MKT y Turnos DT'!$G$6:$G$456,"Hotel") -> 0 | M8: =SUMIFS('Eventos B2B_MKT y Turnos DT'!$K$6:$K$456,'Eventos B2B_MKT y Turnos DT'!$D$6:$D$456,Resumen!$B8,'Eventos B2B_MKT y Turnos DT'!$G$6:$G$456,"Marketing") -> 0 | N8: =SUMIF(Incidencias!$E$4:$E$89,$B8,Incidencias!$K$4:$K$89) -> 0 | O8: =SUM(D8:N8) -> 0 | P8: 29990 | R8: =IFERROR(Q8/O8,0) -> 0 | S8: =IFERROR(P8-Q8,"") -> 29990 | T8: =O8*(1-0.1525)-Q8 -> 0
B9: =Nómina!D6 -> 15688433-2 | C9: =Nómina!E6 -> ANA MARIA POZAS WISTUBA | D9: =SUMIFS(BASE!$Q$3:$Q$453,BASE!$O$3:$O$453,Resumen!D$5,BASE!$B$3:$B$453,Resumen!$B9) -> 0 | E9: =SUMIFS(BASE!$Q$3:$Q$453,BASE!$O$3:$O$453,Resumen!E$5,BASE!$B$3:$B$453,Resumen!$B9) -> 0 | F9: =SUMIFS(BASE!$Q$3:$Q$453,BASE!$O$3:$O$453,Resumen!F$5,BASE!$B$3:$B$453,Resumen!$B9) -> 0 | G9: =SUMIFS(BASE!$Q$3:$Q$453,BASE!$O$3:$O$453,Resumen!G$5,BASE!$B$3:$B$453,Resumen!$B9) -> 0 | H9: =SUMIFS(BASE!$Q$3:$Q$453,BASE!$O$3:$O$453,Resumen!H$5,BASE!$B$3:$B$453,Resumen!$B9) -> 0 | I9: =SUMIFS(BASE!$Q$3:$Q$453,BASE!$O$3:$O$453,Resumen!I$5,BASE!$B$3:$B$453,Resumen!$B9) -> 0 | J9: =SUMIFS(BASE!$Q$3:$Q$453,BASE!$O$3:$O$453,Resumen!J$5,BASE!$B$3:$B$453,Resumen!$B9) -> 0 | K9: =SUMIFS('Eventos B2B_MKT y Turnos DT'!$K$6:$K$456,'Eventos B2B_MKT y Turnos DT'!$D$6:$D$456,Resumen!$B9,'Eventos B2B_MKT y Turnos DT'!$G$6:$G$456,"B2B") -> 0 | L9: =SUMIFS('Eventos B2B_MKT y Turnos DT'!$K$6:$K$456,'Eventos B2B_MKT y Turnos DT'!$D$6:$D$456,Resumen!$B9,'Eventos B2B_MKT y Turnos DT'!$G$6:$G$456,"Hotel") -> 0 | M9: =SUMIFS('Eventos B2B_MKT y Turnos DT'!$K$6:$K$456,'Eventos B2B_MKT y Turnos DT'!$D$6:$D$456,Resumen!$B9,'Eventos B2B_MKT y Turnos DT'!$G$6:$G$456,"Marketing") -> 0 | N9: =SUMIF(Incidencias!$E$4:$E$89,$B9,Incidencias!$K$4:$K$89) -> 0 | O9: =SUM(D9:N9) -> 0 | P9: 85000 | R9: =IFERROR(Q9/O9,0) -> 0 | S9: =IFERROR(P9-Q9,"") -> 85000 | T9: =O9*(1-0.1525)-Q9 -> 0
B10: =Nómina!D7 -> 18480921-4 | C10: =Nómina!E7 -> ANDREA JUANA ALVAREZ SEPULVEDA | D10: =SUMIFS(BASE!$Q$3:$Q$453,BASE!$O$3:$O$453,Resumen!D$5,BASE!$B$3:$B$453,Resumen!$B10) -> 0 | E10: =SUMIFS(BASE!$Q$3:$Q$453,BASE!$O$3:$O$453,Resumen!E$5,BASE!$B$3:$B$453,Resumen!$B10) -> 0 | F10: =SUMIFS(BASE!$Q$3:$Q$453,BASE!$O$3:$O$453,Resumen!F$5,BASE!$B$3:$B$453,Resumen!$B10) -> 0 | G10: =SUMIFS(BASE!$Q$3:$Q$453,BASE!$O$3:$O$453,Resumen!G$5,BASE!$B$3:$B$453,Resumen!$B10) -> 0 | H10: =SUMIFS(BASE!$Q$3:$Q$453,BASE!$O$3:$O$453,Resumen!H$5,BASE!$B$3:$B$453,Resumen!$B10) -> 0 | I10: =SUMIFS(BASE!$Q$3:$Q$453,BASE!$O$3:$O$453,Resumen!I$5,BASE!$B$3:$B$453,Resumen!$B10) -> 0 | J10: =SUMIFS(BASE!$Q$3:$Q$453,BASE!$O$3:$O$453,Resumen!J$5,BASE!$B$3:$B$453,Resumen!$B10) -> 0 | K10: =SUMIFS('Eventos B2B_MKT y Turnos DT'!$K$6:$K$456,'Eventos B2B_MKT y Turnos DT'!$D$6:$D$456,Resumen!$B10,'Eventos B2B_MKT y Turnos DT'!$G$6:$G$456,"B2B") -> 0 | L10: =SUMIFS('Eventos B2B_MKT y Turnos DT'!$K$6:$K$456,'Eventos B2B_MKT y Turnos DT'!$D$6:$D$456,Resumen!$B10,'Eventos B2B_MKT y Turnos DT'!$G$6:$G$456,"Hotel") -> 0 | M10: =SUMIFS('Eventos B2B_MKT y Turnos DT'!$K$6:$K$456,'Eventos B2B_MKT y Turnos DT'!$D$6:$D$456,Resumen!$B10,'Eventos B2B_MKT y Turnos DT'!$G$6:$G$456,"Marketing") -> 0 | N10: =SUMIF(Incidencias!$E$4:$E$89,$B10,Incidencias!$K$4:$K$89) -> 0 | O10: =SUM(D10:N10) -> 0 | P10: 0 | R10: =IFERROR(Q10/O10,0) -> 0 | S10: =IFERROR(P10-Q10,"") -> 0 | T10: =O10*(1-0.1525)-Q10 -> 0
B11: =Nómina!D8 -> 24133147-4 | C11: =Nómina!E8 -> ANGEL LOPEZ FERNANDEZ | D11: =SUMIFS(BASE!$Q$3:$Q$453,BASE!$O$3:$O$453,Resumen!D$5,BASE!$B$3:$B$453,Resumen!$B11) -> 0 | E11: =SUMIFS(BASE!$Q$3:$Q$453,BASE!$O$3:$O$453,Resumen!E$5,BASE!$B$3:$B$453,Resumen!$B11) -> 0 | F11: =SUMIFS(BASE!$Q$3:$Q$453,BASE!$O$3:$O$453,Resumen!F$5,BASE!$B$3:$B$453,Resumen!$B11) -> 0 | G11: =SUMIFS(BASE!$Q$3:$Q$453,BASE!$O$3:$O$453,Resumen!G$5,BASE!$B$3:$B$453,Resumen!$B11) -> 0 | H11: =SUMIFS(BASE!$Q$3:$Q$453,BASE!$O$3:$O$453,Resumen!H$5,BASE!$B$3:$B$453,Resumen!$B11) -> 0 | I11: =SUMIFS(BASE!$Q$3:$Q$453,BASE!$O$3:$O$453,Resumen!I$5,BASE!$B$3:$B$453,Resumen!$B11) -> 0 | J11: =SUMIFS(BASE!$Q$3:$Q$453,BASE!$O$3:$O$453,Resumen!J$5,BASE!$B$3:$B$453,Resumen!$B11) -> 0 | K11: =SUMIFS('Eventos B2B_MKT y Turnos DT'!$K$6:$K$456,'Eventos B2B_MKT y Turnos DT'!$D$6:$D$456,Resumen!$B11,'Eventos B2B_MKT y Turnos DT'!$G$6:$G$456,"B2B") -> 0 | L11: =SUMIFS('Eventos B2B_MKT y Turnos DT'!$K$6:$K$456,'Eventos B2B_MKT y Turnos DT'!$D$6:$D$456,Resumen!$B11,'Eventos B2B_MKT y Turnos DT'!$G$6:$G$456,"Hotel") -> 0 | M11: =SUMIFS('Eventos B2B_MKT y Turnos DT'!$K$6:$K$456,'Eventos B2B_MKT y Turnos DT'!$D$6:$D$456,Resumen!$B11,'Eventos B2B_MKT y Turnos DT'!$G$6:$G$456,"Marketing") -> 0 | N11: =SUMIF(Incidencias!$E$4:$E$89,$B11,Incidencias!$K$4:$K$89) -> 0 | O11: =SUM(D11:N11) -> 0 | P11: 112420 | R11: =IFERROR(Q11/O11,0) -> 0 | S11: =IFERROR(P11-Q11,"") -> 112420 | T11: =O11*(1-0.1525)-Q11 -> 0
B12: =Nómina!D9 -> 26538149-9 | C12: =Nómina!E9 -> ANGELO JESUS OLMOS DEL VALLE | D12: =SUMIFS(BASE!$Q$3:$Q$453,BASE!$O$3:$O$453,Resumen!D$5,BASE!$B$3:$B$453,Resumen!$B12) -> 0 | E12: =SUMIFS(BASE!$Q$3:$Q$453,BASE!$O$3:$O$453,Resumen!E$5,BASE!$B$3:$B$453,Resumen!$B12) -> 0 | F12: =SUMIFS(BASE!$Q$3:$Q$453,BASE!$O$3:$O$453,Resumen!F$5,BASE!$B$3:$B$453,Resumen!$B12) -> 0 | G12: =SUMIFS(BASE!$Q$3:$Q$453,BASE!$O$3:$O$453,Resumen!G$5,BASE!$B$3:$B$453,Resumen!$B12) -> 0 | H12: =SUMIFS(BASE!$Q$3:$Q$453,BASE!$O$3:$O$453,Resumen!H$5,BASE!$B$3:$B$453,Resumen!$B12) -> 0 | I12: =SUMIFS(BASE!$Q$3:$Q$453,BASE!$O$3:$O$453,Resumen!I$5,BASE!$B$3:$B$453,Resumen!$B12) -> 0 | J12: =SUMIFS(BASE!$Q$3:$Q$453,BASE!$O$3:$O$453,Resumen!J$5,BASE!$B$3:$B$453,Resumen!$B12) -> 0 | K12: =SUMIFS('Eventos B2B_MKT y Turnos DT'!$K$6:$K$456,'Eventos B2B_MKT y Turnos DT'!$D$6:$D$456,Resumen!$B12,'Eventos B2B_MKT y Turnos DT'!$G$6:$G$456,"B2B") -> 0 | L12: =SUMIFS('Eventos B2B_MKT y Turnos DT'!$K$6:$K$456,'Eventos B2B_MKT y Turnos DT'!$D$6:$D$456,Resumen!$B12,'Eventos B2B_MKT y Turnos DT'!$G$6:$G$456,"Hotel") -> 0 | M12: =SUMIFS('Eventos B2B_MKT y Turnos DT'!$K$6:$K$456,'Eventos B2B_MKT y Turnos DT'!$D$6:$D$456,Resumen!$B12,'Eventos B2B_MKT y Turnos DT'!$G$6:$G$456,"Marketing") -> 0 | N12: =SUMIF(Incidencias!$E$4:$E$89,$B12,Incidencias!$K$4:$K$89) -> 0 | O12: =SUM(D12:N12) -> 0 | P12: 48500 | Q12: 9500 | R12: =IFERROR(Q12/O12,0) -> 0 | S12: =IFERROR(P12-Q12,"") -> 39000 | T12: =O12*(1-0.1525)-Q12 -> -9500 | U12: =+IF(O12*(1-0.1525)-Q12=T12,"OK","REVISAR") -> OK
B13: =Nómina!D10 -> 26920431-1 | C13: =Nómina!E10 -> ARLIDIS MARIA SANCHEZ CAMACHO | D13: =SUMIFS(BASE!$Q$3:$Q$453,BASE!$O$3:$O$453,Resumen!D$5,BASE!$B$3:$B$453,Resumen!$B13) -> 0 | E13: =SUMIFS(BASE!$Q$3:$Q$453,BASE!$O$3:$O$453,Resumen!E$5,BASE!$B$3:$B$453,Resumen!$B13) -> 0 | F13: =SUMIFS(BASE!$Q$3:$Q$453,BASE!$O$3:$O$453,Resumen!F$5,BASE!$B$3:$B$453,Resumen!$B13) -> 0 | G13: =SUMIFS(BASE!$Q$3:$Q$453,BASE!$O$3:$O$453,Resumen!G$5,BASE!$B$3:$B$453,Resumen!$B13) -> 0 | H13: =SUMIFS(BASE!$Q$3:$Q$453,BASE!$O$3:$O$453,Resumen!H$5,BASE!$B$3:$B$453,Resumen!$B13) -> 0 | I13: =SUMIFS(BASE!$Q$3:$Q$453,BASE!$O$3:$O$453,Resumen!I$5,BASE!$B$3:$B$453,Resumen!$B13) -> 0 | J13: =SUMIFS(BASE!$Q$3:$Q$453,BASE!$O$3:$O$453,Resumen!J$5,BASE!$B$3:$B$453,Resumen!$B13) -> 0 | K13: =SUMIFS('Eventos B2B_MKT y Turnos DT'!$K$6:$K$456,'Eventos B2B_MKT y Turnos DT'!$D$6:$D$456,Resumen!$B13,'Eventos B2B_MKT y Turnos DT'!$G$6:$G$456,"B2B") -> 0 | L13: =SUMIFS('Eventos B2B_MKT y Turnos DT'!$K$6:$K$456,'Eventos B2B_MKT y Turnos DT'!$D$6:$D$456,Resumen!$B13,'Eventos B2B_MKT y Turnos DT'!$G$6:$G$456,"Hotel") -> 0 | M13: =SUMIFS('Eventos B2B_MKT y Turnos DT'!$K$6:$K$456,'Eventos B2B_MKT y Turnos DT'!$D$6:$D$456,Resumen!$B13,'Eventos B2B_MKT y Turnos DT'!$G$6:$G$456,"Marketing") -> 0 | N13: =SUMIF(Incidencias!$E$4:$E$89,$B13,Incidencias!$K$4:$K$89) -> 0 | O13: =SUM(D13:N13) -> 0 | P13: 58473 | R13: =IFERROR(Q13/O13,0) -> 0 | S13: =IFERROR(P13-Q13,"") -> 58473 | T13: =O13*(1-0.1525)-Q13 -> 0
B14: =Nómina!D11 -> 16586101-9 | C14: =Nómina!E11 -> BETTINA GAJARDO | D14: =SUMIFS(BASE!$Q$3:$Q$453,BASE!$O$3:$O$453,Resumen!D$5,BASE!$B$3:$B$453,Resumen!$B14) -> 0 | E14: =SUMIFS(BASE!$Q$3:$Q$453,BASE!$O$3:$O$453,Resumen!E$5,BASE!$B$3:$B$453,Resumen!$B14) -> 0 | F14: =SUMIFS(BASE!$Q$3:$Q$453,BASE!$O$3:$O$453,Resumen!F$5,BASE!$B$3:$B$453,Resumen!$B14) -> 0 | G14: =SUMIFS(BASE!$Q$3:$Q$453,BASE!$O$3:$O$453,Resumen!G$5,BASE!$B$3:$B$453,Resumen!$B14) -> 0 | H14: =SUMIFS(BASE!$Q$3:$Q$453,BASE!$O$3:$O$453,Resumen!H$5,BASE!$B$3:$B$453,Resumen!$B14) -> 0 | I14: =SUMIFS(BASE!$Q$3:$Q$453,BASE!$O$3:$O$453,Resumen!I$5,BASE!$B$3:$B$453,Resumen!$B14) -> 22689 | J14: =SUMIFS(BASE!$Q$3:$Q$453,BASE!$O$3:$O$453,Resumen!J$5,BASE!$B$3:$B$453,Resumen!$B14) -> 0 | K14: =SUMIFS('Eventos B2B_MKT y Turnos DT'!$K$6:$K$456,'Eventos B2B_MKT y Turnos DT'!$D$6:$D$456,Resumen!$B14,'Eventos B2B_MKT y Turnos DT'!$G$6:$G$456,"B2B") -> 0 | L14: =SUMIFS('Eventos B2B_MKT y Turnos DT'!$K$6:$K$456,'Eventos B2B_MKT y Turnos DT'!$D$6:$D$456,Resumen!$B14,'Eventos B2B_MKT y Turnos DT'!$G$6:$G$456,"Hotel") -> 0 | M14: =SUMIFS('Eventos B2B_MKT y Turnos DT'!$K$6:$K$456,'Eventos B2B_MKT y Turnos DT'!$D$6:$D$456,Resumen!$B14,'Eventos B2B_MKT y Turnos DT'!$G$6:$G$456,"Marketing") -> 0 | N14: =SUMIF(Incidencias!$E$4:$E$89,$B14,Incidencias!$K$4:$K$89) -> 0 | O14: =SUM(D14:N14) -> 22689 | P14: 0 | Q14: =+IF(AND(P14<>0,P14>O14*0.2),O14*0.2,P14) -> 0 | R14: =IFERROR(Q14/O14,0) -> 0 | S14: =IFERROR(P14-Q14,"") -> 0 | T14: =O14*(1-0.1525)-Q14 -> 19228.928 | U14: =+IF(O14*(1-0.1525)-Q14=T14,"OK","REVISAR") -> OK
B15: =Nómina!D12 -> 16910373-9 | C15: =Nómina!E12 -> CAMILA ANDREA VILLASECA AZOCAR | D15: =SUMIFS(BASE!$Q$3:$Q$453,BASE!$O$3:$O$453,Resumen!D$5,BASE!$B$3:$B$453,Resumen!$B15) -> 0 | E15: =SUMIFS(BASE!$Q$3:$Q$453,BASE!$O$3:$O$453,Resumen!E$5,BASE!$B$3:$B$453,Resumen!$B15) -> 0 | F15: =SUMIFS(BASE!$Q$3:$Q$453,BASE!$O$3:$O$453,Resumen!F$5,BASE!$B$3:$B$453,Resumen!$B15) -> 0 | G15: =SUMIFS(BASE!$Q$3:$Q$453,BASE!$O$3:$O$453,Resumen!G$5,BASE!$B$3:$B$453,Resumen!$B15) -> 0 | H15: =SUMIFS(BASE!$Q$3:$Q$453,BASE!$O$3:$O$453,Resumen!H$5,BASE!$B$3:$B$453,Resumen!$B15) -> 0 | I15: =SUMIFS(BASE!$Q$3:$Q$453,BASE!$O$3:$O$453,Resumen!I$5,BASE!$B$3:$B$453,Resumen!$B15) -> 0 | J15: =SUMIFS(BASE!$Q$3:$Q$453,BASE!$O$3:$O$453,Resumen!J$5,BASE!$B$3:$B$453,Resumen!$B15) -> 0 | K15: =SUMIFS('Eventos B2B_MKT y Turnos DT'!$K$6:$K$456,'Eventos B2B_MKT y Turnos DT'!$D$6:$D$456,Resumen!$B15,'Eventos B2B_MKT y Turnos DT'!$G$6:$G$456,"B2B") -> 0 | L15: =SUMIFS('Eventos B2B_MKT y Turnos DT'!$K$6:$K$456,'Eventos B2B_MKT y Turnos DT'!$D$6:$D$456,Resumen!$B15,'Eventos B2B_MKT y Turnos DT'!$G$6:$G$456,"Hotel") -> 0 | M15: =SUMIFS('Eventos B2B_MKT y Turnos DT'!$K$6:$K$456,'Eventos B2B_MKT y Turnos DT'!$D$6:$D$456,Resumen!$B15,'Eventos B2B_MKT y Turnos DT'!$G$6:$G$456,"Marketing") -> 0 | N15: =SUMIF(Incidencias!$E$4:$E$89,$B15,Incidencias!$K$4:$K$89) -> 0 | O15: =SUM(D15:N15) -> 0 | P15: 97999.697 | Q15: 19106 | R15: =IFERROR(Q15/O15,0) -> 0 | S15: =IFERROR(P15-Q15,"") -> 78893.697 | T15: =O15*(1-0.1525)-Q15 -> -19106 | U15: =+IF(O15*(1-0.1525)-Q15=T15,"OK","REVISAR") -> OK
B16: =Nómina!D13 -> 17326936-6 | C16: =Nómina!E13 -> CAMILO LOPEZ OMINAMI | D16: =SUMIFS(BASE!$Q$3:$Q$453,BASE!$O$3:$O$453,Resumen!D$5,BASE!$B$3:$B$453,Resumen!$B16) -> 0 | E16: =SUMIFS(BASE!$Q$3:$Q$453,BASE!$O$3:$O$453,Resumen!E$5,BASE!$B$3:$B$453,Resumen!$B16) -> 0 | F16: =SUMIFS(BASE!$Q$3:$Q$453,BASE!$O$3:$O$453,Resumen!F$5,BASE!$B$3:$B$453,Resumen!$B16) -> 0 | G16: =SUMIFS(BASE!$Q$3:$Q$453,BASE!$O$3:$O$453,Resumen!G$5,BASE!$B$3:$B$453,Resumen!$B16) -> 0 | H16: =SUMIFS(BASE!$Q$3:$Q$453,BASE!$O$3:$O$453,Resumen!H$5,BASE!$B$3:$B$453,Resumen!$B16) -> 0 | I16: =SUMIFS(BASE!$Q$3:$Q$453,BASE!$O$3:$O$453,Resumen!I$5,BASE!$B$3:$B$453,Resumen!$B16) -> 0 | J16: =SUMIFS(BASE!$Q$3:$Q$453,BASE!$O$3:$O$453,Resumen!J$5,BASE!$B$3:$B$453,Resumen!$B16) -> 0 | K16: =SUMIFS('Eventos B2B_MKT y Turnos DT'!$K$6:$K$456,'Eventos B2B_MKT y Turnos DT'!$D$6:$D$456,Resumen!$B16,'Eventos B2B_MKT y Turnos DT'!$G$6:$G$456,"B2B") -> 0 | L16: =SUMIFS('Eventos B2B_MKT y Turnos DT'!$K$6:$K$456,'Eventos B2B_MKT y Turnos DT'!$D$6:$D$456,Resumen!$B16,'Eventos B2B_MKT y Turnos DT'!$G$6:$G$456,"Hotel") -> 0 | M16: =SUMIFS('Eventos B2B_MKT y Turnos DT'!$K$6:$K$456,'Eventos B2B_MKT y Turnos DT'!$D$6:$D$456,Resumen!$B16,'Eventos B2B_MKT y Turnos DT'!$G$6:$G$456,"Marketing") -> 0 | N16: =SUMIF(Incidencias!$E$4:$E$89,$B16,Incidencias!$K$4:$K$89) -> 0 | O16: =SUM(D16:N16) -> 0 | P16: 4.9960036e-16 | Q16: =+IF(AND(P16<>0,P16>O16*0.2),O16*0.2,P16) -> 0 | R16: =IFERROR(Q16/O16,0) -> 0 | S16: =IFERROR(P16-Q16,"") -> 4.9960036e-16 | T16: =O16*(1-0.1525)-Q16 -> 0 | U16: =+IF(O16*(1-0.1525)-Q16=T16,"OK","REVISAR") -> OK
B17: =Nómina!D14 -> 21870821-8 | C17: =Nómina!E14 -> CARLA IRELA CARMONA ARTURO | D17: =SUMIFS(BASE!$Q$3:$Q$453,BASE!$O$3:$O$453,Resumen!D$5,BASE!$B$3:$B$453,Resumen!$B17) -> 0 | E17: =SUMIFS(BASE!$Q$3:$Q$453,BASE!$O$3:$O$453,Resumen!E$5,BASE!$B$3:$B$453,Resumen!$B17) -> 0 | F17: =SUMIFS(BASE!$Q$3:$Q$453,BASE!$O$3:$O$453,Resumen!F$5,BASE!$B$3:$B$453,Resumen!$B17) -> 0 | G17: =SUMIFS(BASE!$Q$3:$Q$453,BASE!$O$3:$O$453,Resumen!G$5,BASE!$B$3:$B$453,Resumen!$B17) -> 0 | H17: =SUMIFS(BASE!$Q$3:$Q$453,BASE!$O$3:$O$453,Resumen!H$5,BASE!$B$3:$B$453,Resumen!$B17) -> 0 | I17: =SUMIFS(BASE!$Q$3:$Q$453,BASE!$O$3:$O$453,Resumen!I$5,BASE!$B$3:$B$453,Resumen!$B17) -> 0 | J17: =SUMIFS(BASE!$Q$3:$Q$453,BASE!$O$3:$O$453,Resumen!J$5,BASE!$B$3:$B$453,Resumen!$B17) -> 0 | K17: =SUMIFS('Eventos B2B_MKT y Turnos DT'!$K$6:$K$456,'Eventos B2B_MKT y Turnos DT'!$D$6:$D$456,Resumen!$B17,'Eventos B2B_MKT y Turnos DT'!$G$6:$G$456,"B2B") -> 0 | L17: =SUMIFS('Eventos B2B_MKT y Turnos DT'!$K$6:$K$456,'Eventos B2B_MKT y Turnos DT'!$D$6:$D$456,Resumen!$B17,'Eventos B2B_MKT y Turnos DT'!$G$6:$G$456,"Hotel") -> 0 | M17: =SUMIFS('Eventos B2B_MKT y Turnos DT'!$K$6:$K$456,'Eventos B2B_MKT y Turnos DT'!$D$6:$D$456,Resumen!$B17,'Eventos B2B_MKT y Turnos DT'!$G$6:$G$456,"Marketing") -> 0 | N17: =SUMIF(Incidencias!$E$4:$E$89,$B17,Incidencias!$K$4:$K$89) -> 0 | O17: =SUM(D17:N17) -> 0 | P17: 136000.03 | R17: =IFERROR(Q17/O17,0) -> 0 | S17: =IFERROR(P17-Q17,"") -> 136000.03 | T17: =O17*(1-0.1525)-Q17 -> 0
B18: =Nómina!D15 -> 17664480-K | C18: =Nómina!E15 -> CARLA VERGARA FUENZALIDA | D18: =SUMIFS(BASE!$Q$3:$Q$453,BASE!$O$3:$O$453,Resumen!D$5,BASE!$B$3:$B$453,Resumen!$B18) -> 0 | E18: =SUMIFS(BASE!$Q$3:$Q$453,BASE!$O$3:$O$453,Resumen!E$5,BASE!$B$3:$B$453,Resumen!$B18) -> 0 | F18: =SUMIFS(BASE!$Q$3:$Q$453,BASE!$O$3:$O$453,Resumen!F$5,BASE!$B$3:$B$453,Resumen!$B18) -> 0 | G18: =SUMIFS(BASE!$Q$3:$Q$453,BASE!$O$3:$O$453,Resumen!G$5,BASE!$B$3:$B$453,Resumen!$B18) -> 0 | H18: =SUMIFS(BASE!$Q$3:$Q$453,BASE!$O$3:$O$453,Resumen!H$5,BASE!$B$3:$B$453,Resumen!$B18) -> 0 | I18: =SUMIFS(BASE!$Q$3:$Q$453,BASE!$O$3:$O$453,Resumen!I$5,BASE!$B$3:$B$453,Resumen!$B18) -> 0 | J18: =SUMIFS(BASE!$Q$3:$Q$453,BASE!$O$3:$O$453,Resumen!J$5,BASE!$B$3:$B$453,Resumen!$B18) -> 0 | K18: =SUMIFS('Eventos B2B_MKT y Turnos DT'!$K$6:$K$456,'Eventos B2B_MKT y Turnos DT'!$D$6:$D$456,Resumen!$B18,'Eventos B2B_MKT y Turnos DT'!$G$6:$G$456,"B2B") -> 0 | L18: =SUMIFS('Eventos B2B_MKT y Turnos DT'!$K$6:$K$456,'Eventos B2B_MKT y Turnos DT'!$D$6:$D$456,Resumen!$B18,'Eventos B2B_MKT y Turnos DT'!$G$6:$G$456,"Hotel") -> 0 | M18: =SUMIFS('Eventos B2B_MKT y Turnos DT'!$K$6:$K$456,'Eventos B2B_MKT y Turnos DT'!$D$6:$D$456,Resumen!$B18,'Eventos B2B_MKT y Turnos DT'!$G$6:$G$456,"Marketing") -> 0 | N18: =SUMIF(Incidencias!$E$4:$E$89,$B18,Incidencias!$K$4:$K$89) -> 0 | O18: =SUM(D18:N18) -> 0 | P18: 90000 | R18: =IFERROR(Q18/O18,0) -> 0 | S18: =IFERROR(P18-Q18,"") -> 90000 | T18: =O18*(1-0.1525)-Q18 -> 0
B19: =Nómina!D16 -> 18444844-0 | C19: =Nómina!E16 -> CARMEN GLORIA ADARO CARTAGENA | D19: =SUMIFS(BASE!$Q$3:$Q$453,BASE!$O$3:$O$453,Resumen!D$5,BASE!$B$3:$B$453,Resumen!$B19) -> 0 | E19: =SUMIFS(BASE!$Q$3:$Q$453,BASE!$O$3:$O$453,Resumen!E$5,BASE!$B$3:$B$453,Resumen!$B19) -> 0 | F19: =SUMIFS(BASE!$Q$3:$Q$453,BASE!$O$3:$O$453,Resumen!F$5,BASE!$B$3:$B$453,Resumen!$B19) -> 0 | G19: =SUMIFS(BASE!$Q$3:$Q$453,BASE!$O$3:$O$453,Resumen!G$5,BASE!$B$3:$B$453,Resumen!$B19) -> 0 | H19: =SUMIFS(BASE!$Q$3:$Q$453,BASE!$O$3:$O$453,Resumen!H$5,BASE!$B$3:$B$453,Resumen!$B19) -> 0 | I19: =SUMIFS(BASE!$Q$3:$Q$453,BASE!$O$3:$O$453,Resumen!I$5,BASE!$B$3:$B$453,Resumen!$B19) -> 0 | J19: =SUMIFS(BASE!$Q$3:$Q$453,BASE!$O$3:$O$453,Resumen!J$5,BASE!$B$3:$B$453,Resumen!$B19) -> 0 | K19: =SUMIFS('Eventos B2B_MKT y Turnos DT'!$K$6:$K$456,'Eventos B2B_MKT y Turnos DT'!$D$6:$D$456,Resumen!$B19,'Eventos B2B_MKT y Turnos DT'!$G$6:$G$456,"B2B") -> 0 | L19: =SUMIFS('Eventos B2B_MKT y Turnos DT'!$K$6:$K$456,'Eventos B2B_MKT y Turnos DT'!$D$6:$D$456,Resumen!$B19,'Eventos B2B_MKT y Turnos DT'!$G$6:$G$456,"Hotel") -> 0 | M19: =SUMIFS('Eventos B2B_MKT y Turnos DT'!$K$6:$K$456,'Eventos B2B_MKT y Turnos DT'!$D$6:$D$456,Resumen!$B19,'Eventos B2B_MKT y Turnos DT'!$G$6:$G$456,"Marketing") -> 0 | N19: =SUMIF(Incidencias!$E$4:$E$89,$B19,Incidencias!$K$4:$K$89) -> 0 | O19: =SUM(D19:N19) -> 0 | P19: 133390 | R19: =IFERROR(Q19/O19,0) -> 0 | S19: =IFERROR(P19-Q19,"") -> 133390 | T19: =O19*(1-0.1525)-Q19 -> 0
B20: =Nómina!D17 -> 11229241-1 | C20: =Nómina!E17 -> CARMEN GLORIA TAPIA MORA | D20: =SUMIFS(BASE!$Q$3:$Q$453,BASE!$O$3:$O$453,Resumen!D$5,BASE!$B$3:$B$453,Resumen!$B20) -> 0 | E20: =SUMIFS(BASE!$Q$3:$Q$453,BASE!$O$3:$O$453,Resumen!E$5,BASE!$B$3:$B$453,Resumen!$B20) -> 0 | F20: =SUMIFS(BASE!$Q$3:$Q$453,BASE!$O$3:$O$453,Resumen!F$5,BASE!$B$3:$B$453,Resumen!$B20) -> 0 | G20: =SUMIFS(BASE!$Q$3:$Q$453,BASE!$O$3:$O$453,Resumen!G$5,BASE!$B$3:$B$453,Resumen!$B20) -> 0 | H20: =SUMIFS(BASE!$Q$3:$Q$453,BASE!$O$3:$O$453,Resumen!H$5,BASE!$B$3:$B$453,Resumen!$B20) -> 0 | I20: =SUMIFS(BASE!$Q$3:$Q$453,BASE!$O$3:$O$453,Resumen!I$5,BASE!$B$3:$B$453,Resumen!$B20) -> 0 | J20: =SUMIFS(BASE!$Q$3:$Q$453,BASE!$O$3:$O$453,Resumen!J$5,BASE!$B$3:$B$453,Resumen!$B20) -> 0 | K20: =SUMIFS('Eventos B2B_MKT y Turnos DT'!$K$6:$K$456,'Eventos B2B_MKT y Turnos DT'!$D$6:$D$456,Resumen!$B20,'Eventos B2B_MKT y Turnos DT'!$G$6:$G$456,"B2B") -> 0 | L20: =SUMIFS('Eventos B2B_MKT y Turnos DT'!$K$6:$K$456,'Eventos B2B_MKT y Turnos DT'!$D$6:$D$456,Resumen!$B20,'Eventos B2B_MKT y Turnos DT'!$G$6:$G$456,"Hotel") -> 0 | M20: =SUMIFS('Eventos B2B_MKT y Turnos DT'!$K$6:$K$456,'Eventos B2B_MKT y Turnos DT'!$D$6:$D$456,Resumen!$B20,'Eventos B2B_MKT y Turnos DT'!$G$6:$G$456,"Marketing") -> 0 | N20: =SUMIF(Incidencias!$E$4:$E$89,$B20,Incidencias!$K$4:$K$89) -> 0 | O20: =SUM(D20:N20) -> 0 | P20: 29499 | R20: =IFERROR(Q20/O20,0) -> 0 | S20: =IFERROR(P20-Q20,"") -> 29499 | T20: =O20*(1-0.1525)-Q20 -> 0 | U20: =+IF(O20*(1-0.1525)-Q20=T20,"OK","REVISAR") -> OK
B21: =Nómina!D18 -> 18268581-K | C21: =Nómina!E18 -> CAROLINA ANDREA BUSTOS PONCE | D21: =SUMIFS(BASE!$Q$3:$Q$453,BASE!$O$3:$O$453,Resumen!D$5,BASE!$B$3:$B$453,Resumen!$B21) -> 0 | E21: =SUMIFS(BASE!$Q$3:$Q$453,BASE!$O$3:$O$453,Resumen!E$5,BASE!$B$3:$B$453,Resumen!$B21) -> 0 | F21: =SUMIFS(BASE!$Q$3:$Q$453,BASE!$O$3:$O$453,Resumen!F$5,BASE!$B$3:$B$453,Resumen!$B21) -> 0 | G21: =SUMIFS(BASE!$Q$3:$Q$453,BASE!$O$3:$O$453,Resumen!G$5,BASE!$B$3:$B$453,Resumen!$B21) -> 0 | H21: =SUMIFS(BASE!$Q$3:$Q$453,BASE!$O$3:$O$453,Resumen!H$5,BASE!$B$3:$B$453,Resumen!$B21) -> 0 | I21: =SUMIFS(BASE!$Q$3:$Q$453,BASE!$O$3:$O$453,Resumen!I$5,BASE!$B$3:$B$453,Resumen!$B21) -> 0 | J21: =SUMIFS(BASE!$Q$3:$Q$453,BASE!$O$3:$O$453,Resumen!J$5,BASE!$B$3:$B$453,Resumen!$B21) -> 0 | K21: =SUMIFS('Eventos B2B_MKT y Turnos DT'!$K$6:$K$456,'Eventos B2B_MKT y Turnos DT'!$D$6:$D$456,Resumen!$B21,'Eventos B2B_MKT y Turnos DT'!$G$6:$G$456,"B2B") -> 0 | L21: =SUMIFS('Eventos B2B_MKT y Turnos DT'!$K$6:$K$456,'Eventos B2B_MKT y Turnos DT'!$D$6:$D$456,Resumen!$B21,'Eventos B2B_MKT y Turnos DT'!$G$6:$G$456,"Hotel") -> 0 | M21: =SUMIFS('Eventos B2B_MKT y Turnos DT'!$K$6:$K$456,'Eventos B2B_MKT y Turnos DT'!$D$6:$D$456,Resumen!$B21,'Eventos B2B_MKT y Turnos DT'!$G$6:$G$456,"Marketing") -> 0 | N21: =SUMIF(Incidencias!$E$4:$E$89,$B21,Incidencias!$K$4:$K$89) -> 0 | O21: =SUM(D21:N21) -> 0 | P21: 84000 | R21: =IFERROR(Q21/O21,0) -> 0 | S21: =IFERROR(P21-Q21,"") -> 84000 | T21: =O21*(1-0.1525)-Q21 -> 0
B22: =Nómina!D19 -> 12080901-6 | C22: =Nómina!E19 -> CECILIA CARRAZANA | D22: =SUMIFS(BASE!$Q$3:$Q$453,BASE!$O$3:$O$453,Resumen!D$5,BASE!$B$3:$B$453,Resumen!$B22) -> 0 | E22: =SUMIFS(BASE!$Q$3:$Q$453,BASE!$O$3:$O$453,Resumen!E$5,BASE!$B$3:$B$453,Resumen!$B22) -> 0 | F22: =SUMIFS(BASE!$Q$3:$Q$453,BASE!$O$3:$O$453,Resumen!F$5,BASE!$B$3:$B$453,Resumen!$B22) -> 0 | G22: =SUMIFS(BASE!$Q$3:$Q$453,BASE!$O$3:$O$453,Resumen!G$5,BASE!$B$3:$B$453,Resumen!$B22) -> 0 | H22: =SUMIFS(BASE!$Q$3:$Q$453,BASE!$O$3:$O$453,Resumen!H$5,BASE!$B$3:$B$453,Resumen!$B22) -> 0 | I22: =SUMIFS(BASE!$Q$3:$Q$453,BASE!$O$3:$O$453,Resumen!I$5,BASE!$B$3:$B$453,Resumen!$B22) -> 0 | J22: =SUMIFS(BASE!$Q$3:$Q$453,BASE!$O$3:$O$453,Resumen!J$5,BASE!$B$3:$B$453,Resumen!$B22) -> 0 | K22: =SUMIFS('Eventos B2B_MKT y Turnos DT'!$K$6:$K$456,'Eventos B2B_MKT y Turnos DT'!$D$6:$D$456,Resumen!$B22,'Eventos B2B_MKT y Turnos DT'!$G$6:$G$456,"B2B") -> 0 | L22: =SUMIFS('Eventos B2B_MKT y Turnos DT'!$K$6:$K$456,'Eventos B2B_MKT y Turnos DT'!$D$6:$D$456,Resumen!$B22,'Eventos B2B_MKT y Turnos DT'!$G$6:$G$456,"Hotel") -> 0 | M22: =SUMIFS('Eventos B2B_MKT y Turnos DT'!$K$6:$K$456,'Eventos B2B_MKT y Turnos DT'!$D$6:$D$456,Resumen!$B22,'Eventos B2B_MKT y Turnos DT'!$G$6:$G$456,"Marketing") -> 0 | N22: =SUMIF(Incidencias!$E$4:$E$89,$B22,Incidencias!$K$4:$K$89) -> 0 | O22: =SUM(D22:N22) -> 0 | P22: 84000 | Q22: 6000 | R22: =IFERROR(Q22/O22,0) -> 0 | S22: =IFERROR(P22-Q22,"") -> 78000 | T22: =O22*(1-0.1525)-Q22 -> -6000 | U22: =+IF(O22*(1-0.1525)-Q22=T22,"OK","REVISAR") -> OK
B23: =Nómina!D20 -> 15353076-9 | C23: =Nómina!E20 -> CLAUDIA ALEJANDRA GUZMAN RIGORDI | D23: =SUMIFS(BASE!$Q$3:$Q$453,BASE!$O$3:$O$453,Resumen!D$5,BASE!$B$3:$B$453,Resumen!$B23) -> 99831 | E23: =SUMIFS(BASE!$Q$3:$Q$453,BASE!$O$3:$O$453,Resumen!E$5,BASE!$B$3:$B$453,Resumen!$B23) -> 0 | F23: =SUMIFS(BASE!$Q$3:$Q$453,BASE!$O$3:$O$453,Resumen!F$5,BASE!$B$3:$B$453,Resumen!$B23) -> 0 | G23: =SUMIFS(BASE!$Q$3:$Q$453,BASE!$O$3:$O$453,Resumen!G$5,BASE!$B$3:$B$453,Resumen!$B23) -> 0 | H23: =SUMIFS(BASE!$Q$3:$Q$453,BASE!$O$3:$O$453,Resumen!H$5,BASE!$B$3:$B$453,Resumen!$B23) -> 0 | I23: =SUMIFS(BASE!$Q$3:$Q$453,BASE!$O$3:$O$453,Resumen!I$5,BASE!$B$3:$B$453,Resumen!$B23) -> 0 | J23: =SUMIFS(BASE!$Q$3:$Q$453,BASE!$O$3:$O$453,Resumen!J$5,BASE!$B$3:$B$453,Resumen!$B23) -> 0 | K23: =SUMIFS('Eventos B2B_MKT y Turnos DT'!$K$6:$K$456,'Eventos B2B_MKT y Turnos DT'!$D$6:$D$456,Resumen!$B23,'Eventos B2B_MKT y Turnos DT'!$G$6:$G$456,"B2B") -> 0 | L23: =SUMIFS('Eventos B2B_MKT y Turnos DT'!$K$6:$K$456,'Eventos B2B_MKT y Turnos DT'!$D$6:$D$456,Resumen!$B23,'Eventos B2B_MKT y Turnos DT'!$G$6:$G$456,"Hotel") -> 0 | M23: =SUMIFS('Eventos B2B_MKT y Turnos DT'!$K$6:$K$456,'Eventos B2B_MKT y Turnos DT'!$D$6:$D$456,Resumen!$B23,'Eventos B2B_MKT y Turnos DT'!$G$6:$G$456,"Marketing") -> 0 | N23: =SUMIF(Incidencias!$E$4:$E$89,$B23,Incidencias!$K$4:$K$89) -> 0 | O23: =SUM(D23:N23) -> 99831 | P23: 0 | Q23: =+IF(AND(P23<>0,P23>O23*0.2),O23*0.2,P23) -> 0 | R23: =IFERROR(Q23/O23,0) -> 0 | S23: =IFERROR(P23-Q23,"") -> 0 | T23: =O23*(1-0.1525)-Q23 -> 84606.773 | U23: =+IF(O23*(1-0.1525)-Q23=T23,"OK","REVISAR") -> OK
B24: =Nómina!D21 -> 16725537-K | C24: =Nómina!E21 -> CLAUDIA ANDREA LEYTON FREDES | D24: =SUMIFS(BASE!$Q$3:$Q$453,BASE!$O$3:$O$453,Resumen!D$5,BASE!$B$3:$B$453,Resumen!$B24) -> 0 | E24: =SUMIFS(BASE!$Q$3:$Q$453,BASE!$O$3:$O$453,Resumen!E$5,BASE!$B$3:$B$453,Resumen!$B24) -> 0 | F24: =SUMIFS(BASE!$Q$3:$Q$453,BASE!$O$3:$O$453,Resumen!F$5,BASE!$B$3:$B$453,Resumen!$B24) -> 0 | G24: =SUMIFS(BASE!$Q$3:$Q$453,BASE!$O$3:$O$453,Resumen!G$5,BASE!$B$3:$B$453,Resumen!$B24) -> 0 | H24: =SUMIFS(BASE!$Q$3:$Q$453,BASE!$O$3:$O$453,Resumen!H$5,BASE!$B$3:$B$453,Resumen!$B24) -> 0 | I24: =SUMIFS(BASE!$Q$3:$Q$453,BASE!$O$3:$O$453,Resumen!I$5,BASE!$B$3:$B$453,Resumen!$B24) -> 0 | J24: =SUMIFS(BASE!$Q$3:$Q$453,BASE!$O$3:$O$453,Resumen!J$5,BASE!$B$3:$B$453,Resumen!$B24) -> 0 | K24: =SUMIFS('Eventos B2B_MKT y Turnos DT'!$K$6:$K$456,'Eventos B2B_MKT y Turnos DT'!$D$6:$D$456,Resumen!$B24,'Eventos B2B_MKT y Turnos DT'!$G$6:$G$456,"B2B") -> 0 | L24: =SUMIFS('Eventos B2B_MKT y Turnos DT'!$K$6:$K$456,'Eventos B2B_MKT y Turnos DT'!$D$6:$D$456,Resumen!$B24,'Eventos B2B_MKT y Turnos DT'!$G$6:$G$456,"Hotel") -> 0 | M24: =SUMIFS('Eventos B2B_MKT y Turnos DT'!$K$6:$K$456,'Eventos B2B_MKT y Turnos DT'!$D$6:$D$456,Resumen!$B24,'Eventos B2B_MKT y Turnos DT'!$G$6:$G$456,"Marketing") -> 0 | N24: =SUMIF(Incidencias!$E$4:$E$89,$B24,Incidencias!$K$4:$K$89) -> 0 | O24: =SUM(D24:N24) -> 0 | P24: 273000 | R24: =IFERROR(Q24/O24,0) -> 0 | S24: =IFERROR(P24-Q24,"") -> 273000 | T24: =O24*(1-0.1525)-Q24 -> 0 | U24: =+IF(O24*(1-0.1525)-Q24=T24,"OK","REVISAR") -> OK
B25: =Nómina!D22 -> 13441148-1 | C25: =Nómina!E22 -> CLAUDIA ESTRELLA ESPINOZA CANIUQUEO | D25: =SUMIFS(BASE!$Q$3:$Q$453,BASE!$O$3:$O$453,Resumen!D$5,BASE!$B$3:$B$453,Resumen!$B25) -> 65546 | E25: =SUMIFS(BASE!$Q$3:$Q$453,BASE!$O$3:$O$453,Resumen!E$5,BASE!$B$3:$B$453,Resumen!$B25) -> 0 | F25: =SUMIFS(BASE!$Q$3:$Q$453,BASE!$O$3:$O$453,Resumen!F$5,BASE!$B$3:$B$453,Resumen!$B25) -> 51428 | G25: =SUMIFS(BASE!$Q$3:$Q$453,BASE!$O$3:$O$453,Resumen!G$5,BASE!$B$3:$B$453,Resumen!$B25) -> 0 | H25: =SUMIFS(BASE!$Q$3:$Q$453,BASE!$O$3:$O$453,Resumen!H$5,BASE!$B$3:$B$453,Resumen!$B25) -> 22689 | I25: =SUMIFS(BASE!$Q$3:$Q$453,BASE!$O$3:$O$453,Resumen!I$5,BASE!$B$3:$B$453,Resumen!$B25) -> 0 | J25: =SUMIFS(BASE!$Q$3:$Q$453,BASE!$O$3:$O$453,Resumen!J$5,BASE!$B$3:$B$453,Resumen!$B25) -> 0 | K25: =SUMIFS('Eventos B2B_MKT y Turnos DT'!$K$6:$K$456,'Eventos B2B_MKT y Turnos DT'!$D$6:$D$456,Resumen!$B25,'Eventos B2B_MKT y Turnos DT'!$G$6:$G$456,"B2B") -> 106639 | L25: =SUMIFS('Eventos B2B_MKT y Turnos DT'!$K$6:$K$456,'Eventos B2B_MKT y Turnos DT'!$D$6:$D$456,Resumen!$B25,'Eventos B2B_MKT y Turnos DT'!$G$6:$G$456,"Hotel") -> 23392 | M25: =SUMIFS('Eventos B2B_MKT y Turnos DT'!$K$6:$K$456,'Eventos B2B_MKT y Turnos DT'!$D$6:$D$456,Resumen!$B25,'Eventos B2B_MKT y Turnos DT'!$G$6:$G$456,"Marketing") -> 0 | N25: =SUMIF(Incidencias!$E$4:$E$89,$B25,Incidencias!$K$4:$K$89) -> 0 | O25: =SUM(D25:N25) -> 269694 | P25: 0 | Q25: =+IF(AND(P25<>0,P25>O25*0.2),O25*0.2,P25) -> 0 | R25: =IFERROR(Q25/O25,0) -> 0 | S25: =IFERROR(P25-Q25,"") -> 0 | T25: =O25*(1-0.1525)-Q25 -> 228565.67 | U25: =+IF(O25*(1-0.1525)-Q25=T25,"OK","REVISAR") -> OK
B26: =Nómina!D23 -> 23098075-6 | C26: =Nómina!E23 -> CLAUDIA MARIA HERNANDEZ CONTRERAS | D26: =SUMIFS(BASE!$Q$3:$Q$453,BASE!$O$3:$O$453,Resumen!D$5,BASE!$B$3:$B$453,Resumen!$B26) -> 22689 | E26: =SUMIFS(BASE!$Q$3:$Q$453,BASE!$O$3:$O$453,Resumen!E$5,BASE!$B$3:$B$453,Resumen!$B26) -> 0 | F26: =SUMIFS(BASE!$Q$3:$Q$453,BASE!$O$3:$O$453,Resumen!F$5,BASE!$B$3:$B$453,Resumen!$B26) -> 0 | G26: =SUMIFS(BASE!$Q$3:$Q$453,BASE!$O$3:$O$453,Resumen!G$5,BASE!$B$3:$B$453,Resumen!$B26) -> 0 | H26: =SUMIFS(BASE!$Q$3:$Q$453,BASE!$O$3:$O$453,Resumen!H$5,BASE!$B$3:$B$453,Resumen!$B26) -> 0 | I26: =SUMIFS(BASE!$Q$3:$Q$453,BASE!$O$3:$O$453,Resumen!I$5,BASE!$B$3:$B$453,Resumen!$B26) -> 0 | J26: =SUMIFS(BASE!$Q$3:$Q$453,BASE!$O$3:$O$453,Resumen!J$5,BASE!$B$3:$B$453,Resumen!$B26) -> 0 | K26: =SUMIFS('Eventos B2B_MKT y Turnos DT'!$K$6:$K$456,'Eventos B2B_MKT y Turnos DT'!$D$6:$D$456,Resumen!$B26,'Eventos B2B_MKT y Turnos DT'!$G$6:$G$456,"B2B") -> 0 | L26: =SUMIFS('Eventos B2B_MKT y Turnos DT'!$K$6:$K$456,'Eventos B2B_MKT y Turnos DT'!$D$6:$D$456,Resumen!$B26,'Eventos B2B_MKT y Turnos DT'!$G$6:$G$456,"Hotel") -> 0 | M26: =SUMIFS('Eventos B2B_MKT y Turnos DT'!$K$6:$K$456,'Eventos B2B_MKT y Turnos DT'!$D$6:$D$456,Resumen!$B26,'Eventos B2B_MKT y Turnos DT'!$G$6:$G$456,"Marketing") -> 0 | N26: =SUMIF(Incidencias!$E$4:$E$89,$B26,Incidencias!$K$4:$K$89) -> 0 | O26: =SUM(D26:N26) -> 22689 | P26: 0 | Q26: =+IF(AND(P26<>0,P26>O26*0.2),O26*0.2,P26) -> 0 | R26: =IFERROR(Q26/O26,0) -> 0 | S26: =IFERROR(P26-Q26,"") -> 0 | T26: =O26*(1-0.1525)-Q26 -> 19228.928 | U26: =+IF(O26*(1-0.1525)-Q26=T26,"OK","REVISAR") -> OK
B27: =Nómina!D24 -> 24560038-0 | C27: =Nómina!E24 -> CLAUDIA MILENA DUQUE RAMIREZ | D27: =SUMIFS(BASE!$Q$3:$Q$453,BASE!$O$3:$O$453,Resumen!D$5,BASE!$B$3:$B$453,Resumen!$B27) -> 0 | E27: =SUMIFS(BASE!$Q$3:$Q$453,BASE!$O$3:$O$453,Resumen!E$5,BASE!$B$3:$B$453,Resumen!$B27) -> 0 | F27: =SUMIFS(BASE!$Q$3:$Q$453,BASE!$O$3:$O$453,Resumen!F$5,BASE!$B$3:$B$453,Resumen!$B27) -> 0 | G27: =SUMIFS(BASE!$Q$3:$Q$453,BASE!$O$3:$O$453,Resumen!G$5,BASE!$B$3:$B$453,Resumen!$B27) -> 0 | H27: =SUMIFS(BASE!$Q$3:$Q$453,BASE!$O$3:$O$453,Resumen!H$5,BASE!$B$3:$B$453,Resumen!$B27) -> 0 | I27: =SUMIFS(BASE!$Q$3:$Q$453,BASE!$O$3:$O$453,Resumen!I$5,BASE!$B$3:$B$453,Resumen!$B27) -> 0 | J27: =SUMIFS(BASE!$Q$3:$Q$453,BASE!$O$3:$O$453,Resumen!J$5,BASE!$B$3:$B$453,Resumen!$B27) -> 0 | K27: =SUMIFS('Eventos B2B_MKT y Turnos DT'!$K$6:$K$456,'Eventos B2B_MKT y Turnos DT'!$D$6:$D$456,Resumen!$B27,'Eventos B2B_MKT y Turnos DT'!$G$6:$G$456,"B2B") -> 0 | L27: =SUMIFS('Eventos B2B_MKT y Turnos DT'!$K$6:$K$456,'Eventos B2B_MKT y Turnos DT'!$D$6:$D$456,Resumen!$B27,'Eventos B2B_MKT y Turnos DT'!$G$6:$G$456,"Hotel") -> 0 | M27: =SUMIFS('Eventos B2B_MKT y Turnos DT'!$K$6:$K$456,'Eventos B2B_MKT y Turnos DT'!$D$6:$D$456,Resumen!$B27,'Eventos B2B_MKT y Turnos DT'!$G$6:$G$456,"Marketing") -> 0 | N27: =SUMIF(Incidencias!$E$4:$E$89,$B27,Incidencias!$K$4:$K$89) -> 0 | O27: =SUM(D27:N27) -> 0 | P27: 34499.59 | R27: =IFERROR(Q27/O27,0) -> 0 | S27: =IFERROR(P27-Q27,"") -> 34499.59 | T27: =O27*(1-0.1525)-Q27 -> 0 | U27: =+IF(O27*(1-0.1525)-Q27=T27,"OK","REVISAR") -> OK
B28: =Nómina!D25 -> 19585499-8 | C28: =Nómina!E25 -> DANIEL ABRAHAM ISAAC PEÑA HERNANDEZ | D28: =SUMIFS(BASE!$Q$3:$Q$453,BASE!$O$3:$O$453,Resumen!D$5,BASE!$B$3:$B$453,Resumen!$B28) -> 0 | E28: =SUMIFS(BASE!$Q$3:$Q$453,BASE!$O$3:$O$453,Resumen!E$5,BASE!$B$3:$B$453,Resumen!$B28) -> 0 | F28: =SUMIFS(BASE!$Q$3:$Q$453,BASE!$O$3:$O$453,Resumen!F$5,BASE!$B$3:$B$453,Resumen!$B28) -> 0 | G28: =SUMIFS(BASE!$Q$3:$Q$453,BASE!$O$3:$O$453,Resumen!G$5,BASE!$B$3:$B$453,Resumen!$B28) -> 0 | H28: =SUMIFS(BASE!$Q$3:$Q$453,BASE!$O$3:$O$453,Resumen!H$5,BASE!$B$3:$B$453,Resumen!$B28) -> 0 | I28: =SUMIFS(BASE!$Q$3:$Q$453,BASE!$O$3:$O$453,Resumen!I$5,BASE!$B$3:$B$453,Resumen!$B28) -> 0 | J28: =SUMIFS(BASE!$Q$3:$Q$453,BASE!$O$3:$O$453,Resumen!J$5,BASE!$B$3:$B$453,Resumen!$B28) -> 0 | K28: =SUMIFS('Eventos B2B_MKT y Turnos DT'!$K$6:$K$456,'Eventos B2B_MKT y Turnos DT'!$D$6:$D$456,Resumen!$B28,'Eventos B2B_MKT y Turnos DT'!$G$6:$G$456,"B2B") -> 0 | L28: =SUMIFS('Eventos B2B_MKT y Turnos DT'!$K$6:$K$456,'Eventos B2B_MKT y Turnos DT'!$D$6:$D$456,Resumen!$B28,'Eventos B2B_MKT y Turnos DT'!$G$6:$G$456,"Hotel") -> 0 | M28: =SUMIFS('Eventos B2B_MKT y Turnos DT'!$K$6:$K$456,'Eventos B2B_MKT y Turnos DT'!$D$6:$D$456,Resumen!$B28,'Eventos B2B_MKT y Turnos DT'!$G$6:$G$456,"Marketing") -> 0 | N28: =SUMIF(Incidencias!$E$4:$E$89,$B28,Incidencias!$K$4:$K$89) -> 0 | O28: =SUM(D28:N28) -> 0 | P28: 0 | Q28: =+IF(AND(P28<>0,P28>O28*0.2),O28*0.2,P28) -> 0 | R28: =IFERROR(Q28/O28,0) -> 0 | S28: =IFERROR(P28-Q28,"") -> 0 | T28: =O28*(1-0.1525)-Q28 -> 0 | U28: =+IF(O28*(1-0.1525)-Q28=T28,"OK","REVISAR") -> OK
B29: =Nómina!D26 -> 15893769-7 | C29: =Nómina!E26 -> DANIELA ANTONIA ALARCON ELIZALDE | D29: =SUMIFS(BASE!$Q$3:$Q$453,BASE!$O$3:$O$453,Resumen!D$5,BASE!$B$3:$B$453,Resumen!$B29) -> 182176 | E29: =SUMIFS(BASE!$Q$3:$Q$453,BASE!$O$3:$O$453,Resumen!E$5,BASE!$B$3:$B$453,Resumen!$B29) -> 0 | F29: =SUMIFS(BASE!$Q$3:$Q$453,BASE!$O$3:$O$453,Resumen!F$5,BASE!$B$3:$B$453,Resumen!$B29) -> 0 | G29: =SUMIFS(BASE!$Q$3:$Q$453,BASE!$O$3:$O$453,Resumen!G$5,BASE!$B$3:$B$453,Resumen!$B29) -> 0 | H29: =SUMIFS(BASE!$Q$3:$Q$453,BASE!$O$3:$O$453,Resumen!H$5,BASE!$B$3:$B$453,Resumen!$B29) -> 0 | I29: =SUMIFS(BASE!$Q$3:$Q$453,BASE!$O$3:$O$453,Resumen!I$5,BASE!$B$3:$B$453,Resumen!$B29) -> 22689 | J29: =SUMIFS(BASE!$Q$3:$Q$453,BASE!$O$3:$O$453,Resumen!J$5,BASE!$B$3:$B$453,Resumen!$B29) -> 0 | K29: =SUMIFS('Eventos B2B_MKT y Turnos DT'!$K$6:$K$456,'Eventos B2B_MKT y Turnos DT'!$D$6:$D$456,Resumen!$B29,'Eventos B2B_MKT y Turnos DT'!$G$6:$G$456,"B2B") -> 0 | L29: =SUMIFS('Eventos B2B_MKT y Turnos DT'!$K$6:$K$456,'Eventos B2B_MKT y Turnos DT'!$D$6:$D$456,Resumen!$B29,'Eventos B2B_MKT y Turnos DT'!$G$6:$G$456,"Hotel") -> 23392 | M29: =SUMIFS('Eventos B2B_MKT y Turnos DT'!$K$6:$K$456,'Eventos B2B_MKT y Turnos DT'!$D$6:$D$456,Resumen!$B29,'Eventos B2B_MKT y Turnos DT'!$G$6:$G$456,"Marketing") -> 0 | N29: =SUMIF(Incidencias!$E$4:$E$89,$B29,Incidencias!$K$4:$K$89) -> 0 | O29: =SUM(D29:N29) -> 228257 | P29: 0 | Q29: =+IF(AND(P29<>0,P29>O29*0.2),O29*0.2,P29) -> 0 | R29: =IFERROR(Q29/O29,0) -> 0 | S29: =IFERROR(P29-Q29,"") -> 0 | T29: =O29*(1-0.1525)-Q29 -> 193447.81 | U29: =+IF(O29*(1-0.1525)-Q29=T29,"OK","REVISAR") -> OK
B30: =Nómina!D27 -> 19948116-9 | C30: =Nómina!E27 -> DANIELA MARIA VARAS DIAZ | D30: =SUMIFS(BASE!$Q$3:$Q$453,BASE!$O$3:$O$453,Resumen!D$5,BASE!$B$3:$B$453,Resumen!$B30) -> 0 | E30: =SUMIFS(BASE!$Q$3:$Q$453,BASE!$O$3:$O$453,Resumen!E$5,BASE!$B$3:$B$453,Resumen!$B30) -> 0 | F30: =SUMIFS(BASE!$Q$3:$Q$453,BASE!$O$3:$O$453,Resumen!F$5,BASE!$B$3:$B$453,Resumen!$B30) -> 0 | G30: =SUMIFS(BASE!$Q$3:$Q$453,BASE!$O$3:$O$453,Resumen!G$5,BASE!$B$3:$B$453,Resumen!$B30) -> 0 | H30: =SUMIFS(BASE!$Q$3:$Q$453,BASE!$O$3:$O$453,Resumen!H$5,BASE!$B$3:$B$453,Resumen!$B30) -> 0 | I30: =SUMIFS(BASE!$Q$3:$Q$453,BASE!$O$3:$O$453,Resumen!I$5,BASE!$B$3:$B$453,Resumen!$B30) -> 0 | J30: =SUMIFS(BASE!$Q$3:$Q$453,BASE!$O$3:$O$453,Resumen!J$5,BASE!$B$3:$B$453,Resumen!$B30) -> 0 | K30: =SUMIFS('Eventos B2B_MKT y Turnos DT'!$K$6:$K$456,'Eventos B2B_MKT y Turnos DT'!$D$6:$D$456,Resumen!$B30,'Eventos B2B_MKT y Turnos DT'!$G$6:$G$456,"B2B") -> 0 | L30: =SUMIFS('Eventos B2B_MKT y Turnos DT'!$K$6:$K$456,'Eventos B2B_MKT y Turnos DT'!$D$6:$D$456,Resumen!$B30,'Eventos B2B_MKT y Turnos DT'!$G$6:$G$456,"Hotel") -> 0 | M30: =SUMIFS('Eventos B2B_MKT y Turnos DT'!$K$6:$K$456,'Eventos B2B_MKT y Turnos DT'!$D$6:$D$456,Resumen!$B30,'Eventos B2B_MKT y Turnos DT'!$G$6:$G$456,"Marketing") -> 0 | N30: =SUMIF(Incidencias!$E$4:$E$89,$B30,Incidencias!$K$4:$K$89) -> 0 | O30: =SUM(D30:N30) -> 0 | P30: 61500 | Q30: 7500 | R30: =IFERROR(Q30/O30,0) -> 0 | S30: =IFERROR(P30-Q30,"") -> 54000 | T30: =O30*(1-0.1525)-Q30 -> -7500 | U30: =+IF(O30*(1-0.1525)-Q30=T30,"OK","REVISAR") -> OK
B31: =Nómina!D28 -> 19668624-K | C31: =Nómina!E28 -> DIEGO JOSE GUERRERO ULLOA | D31: =SUMIFS(BASE!$Q$3:$Q$453,BASE!$O$3:$O$453,Resumen!D$5,BASE!$B$3:$B$453,Resumen!$B31) -> 0 | E31: =SUMIFS(BASE!$Q$3:$Q$453,BASE!$O$3:$O$453,Resumen!E$5,BASE!$B$3:$B$453,Resumen!$B31) -> 0 | F31: =SUMIFS(BASE!$Q$3:$Q$453,BASE!$O$3:$O$453,Resumen!F$5,BASE!$B$3:$B$453,Resumen!$B31) -> 0 | G31: =SUMIFS(BASE!$Q$3:$Q$453,BASE!$O$3:$O$453,Resumen!G$5,BASE!$B$3:$B$453,Resumen!$B31) -> 0 | H31: =SUMIFS(BASE!$Q$3:$Q$453,BASE!$O$3:$O$453,Resumen!H$5,BASE!$B$3:$B$453,Resumen!$B31) -> 0 | I31: =SUMIFS(BASE!$Q$3:$Q$453,BASE!$O$3:$O$453,Resumen!I$5,BASE!$B$3:$B$453,Resumen!$B31) -> 0 | J31: =SUMIFS(BASE!$Q$3:$Q$453,BASE!$O$3:$O$453,Resumen!J$5,BASE!$B$3:$B$453,Resumen!$B31) -> 0 | K31: =SUMIFS('Eventos B2B_MKT y Turnos DT'!$K$6:$K$456,'Eventos B2B_MKT y Turnos DT'!$D$6:$D$456,Resumen!$B31,'Eventos B2B_MKT y Turnos DT'!$G$6:$G$456,"B2B") -> 0 | L31: =SUMIFS('Eventos B2B_MKT y Turnos DT'!$K$6:$K$456,'Eventos B2B_MKT y Turnos DT'!$D$6:$D$456,Resumen!$B31,'Eventos B2B_MKT y Turnos DT'!$G$6:$G$456,"Hotel") -> 0 | M31: =SUMIFS('Eventos B2B_MKT y Turnos DT'!$K$6:$K$456,'Eventos B2B_MKT y Turnos DT'!$D$6:$D$456,Resumen!$B31,'Eventos B2B_MKT y Turnos DT'!$G$6:$G$456,"Marketing") -> 0 | N31: =SUMIF(Incidencias!$E$4:$E$89,$B31,Incidencias!$K$4:$K$89) -> 0 | O31: =SUM(D31:N31) -> 0 | P31: 0 | R31: =IFERROR(Q31/O31,0) -> 0 | S31: =IFERROR(P31-Q31,"") -> 0 | T31: =O31*(1-0.1525)-Q31 -> 0
B32: =Nómina!D29 -> 23785099-8 | C32: =Nómina!E29 -> DIEGO TOBIAS CARDENAS GARCIA | D32: =SUMIFS(BASE!$Q$3:$Q$453,BASE!$O$3:$O$453,Resumen!D$5,BASE!$B$3:$B$453,Resumen!$B32) -> 0 | E32: =SUMIFS(BASE!$Q$3:$Q$453,BASE!$O$3:$O$453,Resumen!E$5,BASE!$B$3:$B$453,Resumen!$B32) -> 0 | F32: =SUMIFS(BASE!$Q$3:$Q$453,BASE!$O$3:$O$453,Resumen!F$5,BASE!$B$3:$B$453,Resumen!$B32) -> 0 | G32: =SUMIFS(BASE!$Q$3:$Q$453,BASE!$O$3:$O$453,Resumen!G$5,BASE!$B$3:$B$453,Resumen!$B32) -> 0 | H32: =SUMIFS(BASE!$Q$3:$Q$453,BASE!$O$3:$O$453,Resumen!H$5,BASE!$B$3:$B$453,Resumen!$B32) -> 0 | I32: =SUMIFS(BASE!$Q$3:$Q$453,BASE!$O$3:$O$453,Resumen!I$5,BASE!$B$3:$B$453,Resumen!$B32) -> 0 | J32: =SUMIFS(BASE!$Q$3:$Q$453,BASE!$O$3:$O$453,Resumen!J$5,BASE!$B$3:$B$453,Resumen!$B32) -> 0 | K32: =SUMIFS('Eventos B2B_MKT y Turnos DT'!$K$6:$K$456,'Eventos B2B_MKT y Turnos DT'!$D$6:$D$456,Resumen!$B32,'Eventos B2B_MKT y Turnos DT'!$G$6:$G$456,"B2B") -> 0 | L32: =SUMIFS('Eventos B2B_MKT y Turnos DT'!$K$6:$K$456,'Eventos B2B_MKT y Turnos DT'!$D$6:$D$456,Resumen!$B32,'Eventos B2B_MKT y Turnos DT'!$G$6:$G$456,"Hotel") -> 0 | M32: =SUMIFS('Eventos B2B_MKT y Turnos DT'!$K$6:$K$456,'Eventos B2B_MKT y Turnos DT'!$D$6:$D$456,Resumen!$B32,'Eventos B2B_MKT y Turnos DT'!$G$6:$G$456,"Marketing") -> 0 | N32: =SUMIF(Incidencias!$E$4:$E$89,$B32,Incidencias!$K$4:$K$89) -> 0 | O32: =SUM(D32:N32) -> 0 | P32: 113273 | R32: =IFERROR(Q32/O32,0) -> 0 | S32: =IFERROR(P32-Q32,"") -> 113273 | T32: =O32*(1-0.1525)-Q32 -> 0
B33: =Nómina!D30 -> 15300506-0 | C33: =Nómina!E30 -> DOMITILA DEL PILAR SERON ALMONACID | D33: =SUMIFS(BASE!$Q$3:$Q$453,BASE!$O$3:$O$453,Resumen!D$5,BASE!$B$3:$B$453,Resumen!$B33) -> 0 | E33: =SUMIFS(BASE!$Q$3:$Q$453,BASE!$O$3:$O$453,Resumen!E$5,BASE!$B$3:$B$453,Resumen!$B33) -> 0 | F33: =SUMIFS(BASE!$Q$3:$Q$453,BASE!$O$3:$O$453,Resumen!F$5,BASE!$B$3:$B$453,Resumen!$B33) -> 0 | G33: =SUMIFS(BASE!$Q$3:$Q$453,BASE!$O$3:$O$453,Resumen!G$5,BASE!$B$3:$B$453,Resumen!$B33) -> 0 | H33: =SUMIFS(BASE!$Q$3:$Q$453,BASE!$O$3:$O$453,Resumen!H$5,BASE!$B$3:$B$453,Resumen!$B33) -> 0 | I33: =SUMIFS(BASE!$Q$3:$Q$453,BASE!$O$3:$O$453,Resumen!I$5,BASE!$B$3:$B$453,Resumen!$B33) -> 0 | J33: =SUMIFS(BASE!$Q$3:$Q$453,BASE!$O$3:$O$453,Resumen!J$5,BASE!$B$3:$B$453,Resumen!$B33) -> 0 | K33: =SUMIFS('Eventos B2B_MKT y Turnos DT'!$K$6:$K$456,'Eventos B2B_MKT y Turnos DT'!$D$6:$D$456,Resumen!$B33,'Eventos B2B_MKT y Turnos DT'!$G$6:$G$456,"B2B") -> 0 | L33: =SUMIFS('Eventos B2B_MKT y Turnos DT'!$K$6:$K$456,'Eventos B2B_MKT y Turnos DT'!$D$6:$D$456,Resumen!$B33,'Eventos B2B_MKT y Turnos DT'!$G$6:$G$456,"Hotel") -> 0 | M33: =SUMIFS('Eventos B2B_MKT y Turnos DT'!$K$6:$K$456,'Eventos B2B_MKT y Turnos DT'!$D$6:$D$456,Resumen!$B33,'Eventos B2B_MKT y Turnos DT'!$G$6:$G$456,"Marketing") -> 0 | N33: =SUMIF(Incidencias!$E$4:$E$89,$B33,Incidencias!$K$4:$K$89) -> 0 | O33: =SUM(D33:N33) -> 0 | P33: 120773 | R33: =IFERROR(Q33/O33,0) -> 0 | S33: =IFERROR(P33-Q33,"") -> 120773 | T33: =O33*(1-0.1525)-Q33 -> 0 | U33: =+IF(O33*(1-0.1525)-Q33=T33,"OK","REVISAR") -> OK
B34: =Nómina!D31 -> 18531533-9 | C34: =Nómina!E31 -> EDUARDO DE LA CUADRA PINO | D34: =SUMIFS(BASE!$Q$3:$Q$453,BASE!$O$3:$O$453,Resumen!D$5,BASE!$B$3:$B$453,Resumen!$B34) -> 0 | E34: =SUMIFS(BASE!$Q$3:$Q$453,BASE!$O$3:$O$453,Resumen!E$5,BASE!$B$3:$B$453,Resumen!$B34) -> 0 | F34: =SUMIFS(BASE!$Q$3:$Q$453,BASE!$O$3:$O$453,Resumen!F$5,BASE!$B$3:$B$453,Resumen!$B34) -> 0 | G34: =SUMIFS(BASE!$Q$3:$Q$453,BASE!$O$3:$O$453,Resumen!G$5,BASE!$B$3:$B$453,Resumen!$B34) -> 0 | H34: =SUMIFS(BASE!$Q$3:$Q$453,BASE!$O$3:$O$453,Resumen!H$5,BASE!$B$3:$B$453,Resumen!$B34) -> 0 | I34: =SUMIFS(BASE!$Q$3:$Q$453,BASE!$O$3:$O$453,Resumen!I$5,BASE!$B$3:$B$453,Resumen!$B34) -> 0 | J34: =SUMIFS(BASE!$Q$3:$Q$453,BASE!$O$3:$O$453,Resumen!J$5,BASE!$B$3:$B$453,Resumen!$B34) -> 0 | K34: =SUMIFS('Eventos B2B_MKT y Turnos DT'!$K$6:$K$456,'Eventos B2B_MKT y Turnos DT'!$D$6:$D$456,Resumen!$B34,'Eventos B2B_MKT y Turnos DT'!$G$6:$G$456,"B2B") -> 0 | L34: =SUMIFS('Eventos B2B_MKT y Turnos DT'!$K$6:$K$456,'Eventos B2B_MKT y Turnos DT'!$D$6:$D$456,Resumen!$B34,'Eventos B2B_MKT y Turnos DT'!$G$6:$G$456,"Hotel") -> 0 | M34: =SUMIFS('Eventos B2B_MKT y Turnos DT'!$K$6:$K$456,'Eventos B2B_MKT y Turnos DT'!$D$6:$D$456,Resumen!$B34,'Eventos B2B_MKT y Turnos DT'!$G$6:$G$456,"Marketing") -> 0 | N34: =SUMIF(Incidencias!$E$4:$E$89,$B34,Incidencias!$K$4:$K$89) -> 0 | O34: =SUM(D34:N34) -> 0 | P34: 28000 | R34: =IFERROR(Q34/O34,0) -> 0 | S34: =IFERROR(P34-Q34,"") -> 28000 | T34: =O34*(1-0.1525)-Q34 -> 0
B35: =Nómina!D32 -> 17495969-2 | C35: =Nómina!E32 -> ELENA MUÑOZ MUÑOZ | D35: =SUMIFS(BASE!$Q$3:$Q$453,BASE!$O$3:$O$453,Resumen!D$5,BASE!$B$3:$B$453,Resumen!$B35) -> 0 | E35: =SUMIFS(BASE!$Q$3:$Q$453,BASE!$O$3:$O$453,Resumen!E$5,BASE!$B$3:$B$453,Resumen!$B35) -> 0 | F35: =SUMIFS(BASE!$Q$3:$Q$453,BASE!$O$3:$O$453,Resumen!F$5,BASE!$B$3:$B$453,Resumen!$B35) -> 0 | G35: =SUMIFS(BASE!$Q$3:$Q$453,BASE!$O$3:$O$453,Resumen!G$5,BASE!$B$3:$B$453,Resumen!$B35) -> 0 | H35: =SUMIFS(BASE!$Q$3:$Q$453,BASE!$O$3:$O$453,Resumen!H$5,BASE!$B$3:$B$453,Resumen!$B35) -> 0 | I35: =SUMIFS(BASE!$Q$3:$Q$453,BASE!$O$3:$O$453,Resumen!I$5,BASE!$B$3:$B$453,Resumen!$B35) -> 0 | J35: =SUMIFS(BASE!$Q$3:$Q$453,BASE!$O$3:$O$453,Resumen!J$5,BASE!$B$3:$B$453,Resumen!$B35) -> 0 | K35: =SUMIFS('Eventos B2B_MKT y Turnos DT'!$K$6:$K$456,'Eventos B2B_MKT y Turnos DT'!$D$6:$D$456,Resumen!$B35,'Eventos B2B_MKT y Turnos DT'!$G$6:$G$456,"B2B") -> 0 | L35: =SUMIFS('Eventos B2B_MKT y Turnos DT'!$K$6:$K$456,'Eventos B2B_MKT y Turnos DT'!$D$6:$D$456,Resumen!$B35,'Eventos B2B_MKT y Turnos DT'!$G$6:$G$456,"Hotel") -> 0 | M35: =SUMIFS('Eventos B2B_MKT y Turnos DT'!$K$6:$K$456,'Eventos B2B_MKT y Turnos DT'!$D$6:$D$456,Resumen!$B35,'Eventos B2B_MKT y Turnos DT'!$G$6:$G$456,"Marketing") -> 0 | N35: =SUMIF(Incidencias!$E$4:$E$89,$B35,Incidencias!$K$4:$K$89) -> 0 | O35: =SUM(D35:N35) -> 0 | P35: 0 | R35: =IFERROR(Q35/O35,0) -> 0 | S35: =IFERROR(P35-Q35,"") -> 0 | T35: =O35*(1-0.1525)-Q35 -> 0 | U35: =+IF(O35*(1-0.1525)-Q35=T35,"OK","REVISAR") -> OK
B36: =Nómina!D33 -> 13230370-3 | C36: =Nómina!E33 -> ESTEBAN MELLA GALLARDO | D36: =SUMIFS(BASE!$Q$3:$Q$453,BASE!$O$3:$O$453,Resumen!D$5,BASE!$B$3:$B$453,Resumen!$B36) -> 0 | E36: =SUMIFS(BASE!$Q$3:$Q$453,BASE!$O$3:$O$453,Resumen!E$5,BASE!$B$3:$B$453,Resumen!$B36) -> 0 | F36: =SUMIFS(BASE!$Q$3:$Q$453,BASE!$O$3:$O$453,Resumen!F$5,BASE!$B$3:$B$453,Resumen!$B36) -> 0 | G36: =SUMIFS(BASE!$Q$3:$Q$453,BASE!$O$3:$O$453,Resumen!G$5,BASE!$B$3:$B$453,Resumen!$B36) -> 0 | H36: =SUMIFS(BASE!$Q$3:$Q$453,BASE!$O$3:$O$453,Resumen!H$5,BASE!$B$3:$B$453,Resumen!$B36) -> 0 | I36: =SUMIFS(BASE!$Q$3:$Q$453,BASE!$O$3:$O$453,Resumen!I$5,BASE!$B$3:$B$453,Resumen!$B36) -> 0 | J36: =SUMIFS(BASE!$Q$3:$Q$453,BASE!$O$3:$O$453,Resumen!J$5,BASE!$B$3:$B$453,Resumen!$B36) -> 0 | K36: =SUMIFS('Eventos B2B_MKT y Turnos DT'!$K$6:$K$456,'Eventos B2B_MKT y Turnos DT'!$D$6:$D$456,Resumen!$B36,'Eventos B2B_MKT y Turnos DT'!$G$6:$G$456,"B2B") -> 0 | L36: =SUMIFS('Eventos B2B_MKT y Turnos DT'!$K$6:$K$456,'Eventos B2B_MKT y Turnos DT'!$D$6:$D$456,Resumen!$B36,'Eventos B2B_MKT y Turnos DT'!$G$6:$G$456,"Hotel") -> 0 | M36: =SUMIFS('Eventos B2B_MKT y Turnos DT'!$K$6:$K$456,'Eventos B2B_MKT y Turnos DT'!$D$6:$D$456,Resumen!$B36,'Eventos B2B_MKT y Turnos DT'!$G$6:$G$456,"Marketing") -> 0 | N36: =SUMIF(Incidencias!$E$4:$E$89,$B36,Incidencias!$K$4:$K$89) -> 0 | O36: =SUM(D36:N36) -> 0 | P36: 0 | R36: =IFERROR(Q36/O36,0) -> 0 | S36: =IFERROR(P36-Q36,"") -> 0 | T36: =O36*(1-0.1525)-Q36 -> 0
B37: =Nómina!D34 -> 12897620-5 | C37: =Nómina!E34 -> EUGENIA ISABEL MONTOYA VIELMA | D37: =SUMIFS(BASE!$Q$3:$Q$453,BASE!$O$3:$O$453,Resumen!D$5,BASE!$B$3:$B$453,Resumen!$B37) -> 70588 | E37: =SUMIFS(BASE!$Q$3:$Q$453,BASE!$O$3:$O$453,Resumen!E$5,BASE!$B$3:$B$453,Resumen!$B37) -> 0 | F37: =SUMIFS(BASE!$Q$3:$Q$453,BASE!$O$3:$O$453,Resumen!F$5,BASE!$B$3:$B$453,Resumen!$B37) -> 22689 | G37: =SUMIFS(BASE!$Q$3:$Q$453,BASE!$O$3:$O$453,Resumen!G$5,BASE!$B$3:$B$453,Resumen!$B37) -> 0 | H37: =SUMIFS(BASE!$Q$3:$Q$453,BASE!$O$3:$O$453,Resumen!H$5,BASE!$B$3:$B$453,Resumen!$B37) -> 0 | I37: =SUMIFS(BASE!$Q$3:$Q$453,BASE!$O$3:$O$453,Resumen!I$5,BASE!$B$3:$B$453,Resumen!$B37) -> 0 | J37: =SUMIFS(BASE!$Q$3:$Q$453,BASE!$O$3:$O$453,Resumen!J$5,BASE!$B$3:$B$453,Resumen!$B37) -> 0 | K37: =SUMIFS('Eventos B2B_MKT y Turnos DT'!$K$6:$K$456,'Eventos B2B_MKT y Turnos DT'!$D$6:$D$456,Resumen!$B37,'Eventos B2B_MKT y Turnos DT'!$G$6:$G$456,"B2B") -> 0 | L37: =SUMIFS('Eventos B2B_MKT y Turnos DT'!$K$6:$K$456,'Eventos B2B_MKT y Turnos DT'!$D$6:$D$456,Resumen!$B37,'Eventos B2B_MKT y Turnos DT'!$G$6:$G$456,"Hotel") -> 0 | M37: =SUMIFS('Eventos B2B_MKT y Turnos DT'!$K$6:$K$456,'Eventos B2B_MKT y Turnos DT'!$D$6:$D$456,Resumen!$B37,'Eventos B2B_MKT y Turnos DT'!$G$6:$G$456,"Marketing") -> 0 | N37: =SUMIF(Incidencias!$E$4:$E$89,$B37,Incidencias!$K$4:$K$89) -> 15000 | O37: =SUM(D37:N37) -> 108277 | P37: 0 | Q37: =+IF(AND(P37<>0,P37>O37*0.2),O37*0.2,P37) -> 0 | R37: =IFERROR(Q37/O37,0) -> 0 | S37: =IFERROR(P37-Q37,"") -> 0 | T37: =O37*(1-0.1525)-Q37 -> 91764.758 | U37: =+IF(O37*(1-0.1525)-Q37=T37,"OK","REVISAR") -> OK
B38: =Nómina!D35 -> 17379695-1 | C38: =Nómina!E35 -> FRANCISCA ANGELICA ROJAS VILCH | D38: =SUMIFS(BASE!$Q$3:$Q$453,BASE!$O$3:$O$453,Resumen!D$5,BASE!$B$3:$B$453,Resumen!$B38) -> 0 | E38: =SUMIFS(BASE!$Q$3:$Q$453,BASE!$O$3:$O$453,Resumen!E$5,BASE!$B$3:$B$453,Resumen!$B38) -> 0 | F38: =SUMIFS(BASE!$Q$3:$Q$453,BASE!$O$3:$O$453,Resumen!F$5,BASE!$B$3:$B$453,Resumen!$B38) -> 0 | G38: =SUMIFS(BASE!$Q$3:$Q$453,BASE!$O$3:$O$453,Resumen!G$5,BASE!$B$3:$B$453,Resumen!$B38) -> 0 | H38: =SUMIFS(BASE!$Q$3:$Q$453,BASE!$O$3:$O$453,Resumen!H$5,BASE!$B$3:$B$453,Resumen!$B38) -> 0 | I38: =SUMIFS(BASE!$Q$3:$Q$453,BASE!$O$3:$O$453,Resumen!I$5,BASE!$B$3:$B$453,Resumen!$B38) -> 0 | J38: =SUMIFS(BASE!$Q$3:$Q$453,BASE!$O$3:$O$453,Resumen!J$5,BASE!$B$3:$B$453,Resumen!$B38) -> 0 | K38: =SUMIFS('Eventos B2B_MKT y Turnos DT'!$K$6:$K$456,'Eventos B2B_MKT y Turnos DT'!$D$6:$D$456,Resumen!$B38,'Eventos B2B_MKT y Turnos DT'!$G$6:$G$456,"B2B") -> 0 | L38: =SUMIFS('Eventos B2B_MKT y Turnos DT'!$K$6:$K$456,'Eventos B2B_MKT y Turnos DT'!$D$6:$D$456,Resumen!$B38,'Eventos B2B_MKT y Turnos DT'!$G$6:$G$456,"Hotel") -> 0 | M38: =SUMIFS('Eventos B2B_MKT y Turnos DT'!$K$6:$K$456,'Eventos B2B_MKT y Turnos DT'!$D$6:$D$456,Resumen!$B38,'Eventos B2B_MKT y Turnos DT'!$G$6:$G$456,"Marketing") -> 0 | N38: =SUMIF(Incidencias!$E$4:$E$89,$B38,Incidencias!$K$4:$K$89) -> 0 | O38: =SUM(D38:N38) -> 0 | P38: 0 | R38: =IFERROR(Q38/O38,0) -> 0 | S38: =IFERROR(P38-Q38,"") -> 0 | T38: =O38*(1-0.1525)-Q38 -> 0 | U38: =+IF(O38*(1-0.1525)-Q38=T38,"OK","REVISAR") -> OK
B39: =Nómina!D36 -> 18786881-5 | C39: =Nómina!E36 -> FRANCISCA ARAYA OLGUIN | D39: =SUMIFS(BASE!$Q$3:$Q$453,BASE!$O$3:$O$453,Resumen!D$5,BASE!$B$3:$B$453,Resumen!$B39) -> 0 | E39: =SUMIFS(BASE!$Q$3:$Q$453,BASE!$O$3:$O$453,Resumen!E$5,BASE!$B$3:$B$453,Resumen!$B39) -> 0 | F39: =SUMIFS(BASE!$Q$3:$Q$453,BASE!$O$3:$O$453,Resumen!F$5,BASE!$B$3:$B$453,Resumen!$B39) -> 0 | G39: =SUMIFS(BASE!$Q$3:$Q$453,BASE!$O$3:$O$453,Resumen!G$5,BASE!$B$3:$B$453,Resumen!$B39) -> 0 | H39: =SUMIFS(BASE!$Q$3:$Q$453,BASE!$O$3:$O$453,Resumen!H$5,BASE!$B$3:$B$453,Resumen!$B39) -> 0 | I39: =SUMIFS(BASE!$Q$3:$Q$453,BASE!$O$3:$O$453,Resumen!I$5,BASE!$B$3:$B$453,Resumen!$B39) -> 0 | J39: =SUMIFS(BASE!$Q$3:$Q$453,BASE!$O$3:$O$453,Resumen!J$5,BASE!$B$3:$B$453,Resumen!$B39) -> 0 | K39: =SUMIFS('Eventos B2B_MKT y Turnos DT'!$K$6:$K$456,'Eventos B2B_MKT y Turnos DT'!$D$6:$D$456,Resumen!$B39,'Eventos B2B_MKT y Turnos DT'!$G$6:$G$456,"B2B") -> 0 | L39: =SUMIFS('Eventos B2B_MKT y Turnos DT'!$K$6:$K$456,'Eventos B2B_MKT y Turnos DT'!$D$6:$D$456,Resumen!$B39,'Eventos B2B_MKT y Turnos DT'!$G$6:$G$456,"Hotel") -> 0 | M39: =SUMIFS('Eventos B2B_MKT y Turnos DT'!$K$6:$K$456,'Eventos B2B_MKT y Turnos DT'!$D$6:$D$456,Resumen!$B39,'Eventos B2B_MKT y Turnos DT'!$G$6:$G$456,"Marketing") -> 0 | N39: =SUMIF(Incidencias!$E$4:$E$89,$B39,Incidencias!$K$4:$K$89) -> 0 | O39: =SUM(D39:N39) -> 0 | P39: 0 | R39: =IFERROR(Q39/O39,0) -> 0 | S39: =IFERROR(P39-Q39,"") -> 0 | T39: =O39*(1-0.1525)-Q39 -> 0 | U39: =+IF(O39*(1-0.1525)-Q39=T39,"OK","REVISAR") -> OK
B40: =Nómina!D37 -> 16744004-5 | C40: =Nómina!E37 -> FRANCISCA PAULA SAAVEDRA ROJAS | D40: =SUMIFS(BASE!$Q$3:$Q$453,BASE!$O$3:$O$453,Resumen!D$5,BASE!$B$3:$B$453,Resumen!$B40) -> 0 | E40: =SUMIFS(BASE!$Q$3:$Q$453,BASE!$O$3:$O$453,Resumen!E$5,BASE!$B$3:$B$453,Resumen!$B40) -> 0 | F40: =SUMIFS(BASE!$Q$3:$Q$453,BASE!$O$3:$O$453,Resumen!F$5,BASE!$B$3:$B$453,Resumen!$B40) -> 0 | G40: =SUMIFS(BASE!$Q$3:$Q$453,BASE!$O$3:$O$453,Resumen!G$5,BASE!$B$3:$B$453,Resumen!$B40) -> 0 | H40: =SUMIFS(BASE!$Q$3:$Q$453,BASE!$O$3:$O$453,Resumen!H$5,BASE!$B$3:$B$453,Resumen!$B40) -> 0 | I40: =SUMIFS(BASE!$Q$3:$Q$453,BASE!$O$3:$O$453,Resumen!I$5,BASE!$B$3:$B$453,Resumen!$B40) -> 0 | J40: =SUMIFS(BASE!$Q$3:$Q$453,BASE!$O$3:$O$453,Resumen!J$5,BASE!$B$3:$B$453,Resumen!$B40) -> 0 | K40: =SUMIFS('Eventos B2B_MKT y Turnos DT'!$K$6:$K$456,'Eventos B2B_MKT y Turnos DT'!$D$6:$D$456,Resumen!$B40,'Eventos B2B_MKT y Turnos DT'!$G$6:$G$456,"B2B") -> 0 | L40: =SUMIFS('Eventos B2B_MKT y Turnos DT'!$K$6:$K$456,'Eventos B2B_MKT y Turnos DT'!$D$6:$D$456,Resumen!$B40,'Eventos B2B_MKT y Turnos DT'!$G$6:$G$456,"Hotel") -> 0 | M40: =SUMIFS('Eventos B2B_MKT y Turnos DT'!$K$6:$K$456,'Eventos B2B_MKT y Turnos DT'!$D$6:$D$456,Resumen!$B40,'Eventos B2B_MKT y Turnos DT'!$G$6:$G$456,"Marketing") -> 0 | N40: =SUMIF(Incidencias!$E$4:$E$89,$B40,Incidencias!$K$4:$K$89) -> 0 | O40: =SUM(D40:N40) -> 0 | P40: 18500 | R40: =IFERROR(Q40/O40,0) -> 0 | S40: =IFERROR(P40-Q40,"") -> 18500 | T40: =O40*(1-0.1525)-Q40 -> 0 | U40: =+IF(O40*(1-0.1525)-Q40=T40,"OK","REVISAR") -> OK
B41: =Nómina!D38 -> 26598096-1 | C41: =Nómina!E38 -> GENESIS DANIELA PIMENTEL HERRERA | D41: =SUMIFS(BASE!$Q$3:$Q$453,BASE!$O$3:$O$453,Resumen!D$5,BASE!$B$3:$B$453,Resumen!$B41) -> 183025 | E41: =SUMIFS(BASE!$Q$3:$Q$453,BASE!$O$3:$O$453,Resumen!E$5,BASE!$B$3:$B$453,Resumen!$B41) -> 0 | F41: =SUMIFS(BASE!$Q$3:$Q$453,BASE!$O$3:$O$453,Resumen!F$5,BASE!$B$3:$B$453,Resumen!$B41) -> 65546 | G41: =SUMIFS(BASE!$Q$3:$Q$453,BASE!$O$3:$O$453,Resumen!G$5,BASE!$B$3:$B$453,Resumen!$B41) -> 0 | H41: =SUMIFS(BASE!$Q$3:$Q$453,BASE!$O$3:$O$453,Resumen!H$5,BASE!$B$3:$B$453,Resumen!$B41) -> 0 | I41: =SUMIFS(BASE!$Q$3:$Q$453,BASE!$O$3:$O$453,Resumen!I$5,BASE!$B$3:$B$453,Resumen!$B41) -> 0 | J41: =SUMIFS(BASE!$Q$3:$Q$453,BASE!$O$3:$O$453,Resumen!J$5,BASE!$B$3:$B$453,Resumen!$B41) -> 0 | K41: =SUMIFS('Eventos B2B_MKT y Turnos DT'!$K$6:$K$456,'Eventos B2B_MKT y Turnos DT'!$D$6:$D$456,Resumen!$B41,'Eventos B2B_MKT y Turnos DT'!$G$6:$G$456,"B2B") -> 0 | L41: =SUMIFS('Eventos B2B_MKT y Turnos DT'!$K$6:$K$456,'Eventos B2B_MKT y Turnos DT'!$D$6:$D$456,Resumen!$B41,'Eventos B2B_MKT y Turnos DT'!$G$6:$G$456,"Hotel") -> 23392 | M41: =SUMIFS('Eventos B2B_MKT y Turnos DT'!$K$6:$K$456,'Eventos B2B_MKT y Turnos DT'!$D$6:$D$456,Resumen!$B41,'Eventos B2B_MKT y Turnos DT'!$G$6:$G$456,"Marketing") -> 0 | N41: =SUMIF(Incidencias!$E$4:$E$89,$B41,Incidencias!$K$4:$K$89) -> 0 | O41: =SUM(D41:N41) -> 271963 | P41: 0 | Q41: =+IF(AND(P41<>0,P41>O41*0.2),O41*0.2,P41) -> 0 | R41: =IFERROR(Q41/O41,0) -> 0 | S41: =IFERROR(P41-Q41,"") -> 0 | T41: =O41*(1-0.1525)-Q41 -> 230488.64 | U41: =+IF(O41*(1-0.1525)-Q41=T41,"OK","REVISAR") -> OK
B42: =Nómina!D39 -> 27828546-4 | C42: =Nómina!E39 -> GENESIS VALENTINA SALAZAR GUEVARA | D42: =SUMIFS(BASE!$Q$3:$Q$453,BASE!$O$3:$O$453,Resumen!D$5,BASE!$B$3:$B$453,Resumen!$B42) -> 177134 | E42: =SUMIFS(BASE!$Q$3:$Q$453,BASE!$O$3:$O$453,Resumen!E$5,BASE!$B$3:$B$453,Resumen!$B42) -> 0 | F42: =SUMIFS(BASE!$Q$3:$Q$453,BASE!$O$3:$O$453,Resumen!F$5,BASE!$B$3:$B$453,Resumen!$B42) -> 118487 | G42: =SUMIFS(BASE!$Q$3:$Q$453,BASE!$O$3:$O$453,Resumen!G$5,BASE!$B$3:$B$453,Resumen!$B42) -> 0 | H42: =SUMIFS(BASE!$Q$3:$Q$453,BASE!$O$3:$O$453,Resumen!H$5,BASE!$B$3:$B$453,Resumen!$B42) -> 0 | I42: =SUMIFS(BASE!$Q$3:$Q$453,BASE!$O$3:$O$453,Resumen!I$5,BASE!$B$3:$B$453,Resumen!$B42) -> 0 | J42: =SUMIFS(BASE!$Q$3:$Q$453,BASE!$O$3:$O$453,Resumen!J$5,BASE!$B$3:$B$453,Resumen!$B42) -> 0 | K42: =SUMIFS('Eventos B2B_MKT y Turnos DT'!$K$6:$K$456,'Eventos B2B_MKT y Turnos DT'!$D$6:$D$456,Resumen!$B42,'Eventos B2B_MKT y Turnos DT'!$G$6:$G$456,"B2B") -> 0 | L42: =SUMIFS('Eventos B2B_MKT y Turnos DT'!$K$6:$K$456,'Eventos B2B_MKT y Turnos DT'!$D$6:$D$456,Resumen!$B42,'Eventos B2B_MKT y Turnos DT'!$G$6:$G$456,"Hotel") -> 0 | M42: =SUMIFS('Eventos B2B_MKT y Turnos DT'!$K$6:$K$456,'Eventos B2B_MKT y Turnos DT'!$D$6:$D$456,Resumen!$B42,'Eventos B2B_MKT y Turnos DT'!$G$6:$G$456,"Marketing") -> 0 | N42: =SUMIF(Incidencias!$E$4:$E$89,$B42,Incidencias!$K$4:$K$89) -> 0 | O42: =SUM(D42:N42) -> 295621 | P42: 0 | Q42: =+IF(AND(P42<>0,P42>O42*0.2),O42*0.2,P42) -> 0 | R42: =IFERROR(Q42/O42,0) -> 0 | S42: =IFERROR(P42-Q42,"") -> 0 | T42: =O42*(1-0.1525)-Q42 -> 250538.8 | U42: =+IF(O42*(1-0.1525)-Q42=T42,"OK","REVISAR") -> OK
...

Sheet Eventos B2B_MKT y Turnos DT
N2: Líneas de Negocio | O2: B2B | P2: =SUMIF($G$6:$G$55,O2,$K$6:$K$55) -> 509750
O3: Hotel | P3: =SUMIF($G$6:$G$55,O3,$K$6:$K$55) -> 327488
K4: =SUBTOTAL(9,K6:K1048576) -> 837238 | O4: Marketing | P4: =SUMIF($G$6:$G$55,O4,$K$6:$K$55) -> 0
B5: Año | C5: Mes | D5: RUT | E5: Nombre Tp | F5: Fecha Evento | G5: Línea de Negocio | H5: Cliente / Evento | I5: Hrs evento | J5: Tipo Servicio | K5: Comisión
B6: 2026 | C6: 7 | D6: 18725726-3 | E6: RAFAEL EMILIANO RIQUELME VALDEBENITO | F6: 46207 | G6: Hotel | H6: Doubletree Bloque 1 | I6: 4 | J6: Camilla | K6: 23392
B7: 2026 | C7: 7 | D7: 17707188-9 | E7: XIMENA ESTEFANIA PASTEN PINO | F7: 46207 | G7: Hotel | H7: Doubletree Bloque 1 | I7: 4 | J7: Camilla | K7: 23392
B8: 2026 | C8: 7 | D8: 19232974-4 | E8: JOSE IGNACIO PALMA CASANOVA | F8: 46207 | G8: Hotel | H8: Doubletree Bloque 2 | I8: 4 | J8: Camilla | K8: 23392
B9: 2026 | C9: 7 | D9: 13441148-1 | E9: CLAUDIA ESTRELLA ESPINOZA CANIUQUEO | F9: 46207 | G9: Hotel | H9: Doubletree Bloque 2 | I9: 4 | J9: Camilla | K9: 23392
B10: 2026 | C10: 7 | D10: 27988098-6 | E10: SERGIO RODRÍGUEZ | F10: 46208 | G10: Hotel | H10: Doubletree Bloque 1 | I10: 4 | J10: Camilla | K10: 23392
B11: 2026 | C11: 7 | D11: 13715658-K | E11: ALEJANDRA PAZ SANCHEZ LENERO | F11: 46208 | G11: Hotel | H11: Doubletree Bloque 1 | I11: 4 | J11: Camilla | K11: 23392
B12: 2026 | C12: 7 | D12: 17681238-9 | E12: IVVO LEANDRO VERGARA SALINAS | F12: 46208 | G12: Hotel | H12: Doubletree Bloque 2 | I12: 4 | J12: Camilla | K12: 23392
B13: 2026 | C13: 7 | D13: 26330714-3 | E13: WENDY CAROLINA MENDEZ AVENDAÑO | F13: 46210 | G13: B2B | H13: TECHSPERT | I13: 2 | J13: Silla | K13: 41597
B14: 2026 | C14: 7 | D14: 27988098-6 | E14: SERGIO RODRÍGUEZ | F14: 46210 | G14: B2B | H14: TECHSPERT | I14: 2 | J14: Silla | K14: 41597
B15: 2026 | C15: 7 | D15: 17707188-9 | E15: XIMENA ESTEFANIA PASTEN PINO | F15: 46212 | G15: B2B | H15: HATCH | I15: 6 | J15: Silla | K15: 106639
B16: 2026 | C16: 7 | D16: 26330714-3 | E16: WENDY CAROLINA MENDEZ AVENDAÑO | F16: 46212 | G16: B2B | H16: HATCH | I16: 6 | J16: Silla | K16: 106639
B17: 2026 | C17: 7 | D17: 27988098-6 | E17: SERGIO RODRÍGUEZ | F17: 46212 | G17: B2B | H17: HATCH | I17: 6 | J17: Silla | K17: 106639
